Workbook

Sheet U9-U10
A1: World Cup Tournament
B3: Group 1 | N3: Group 2
A5: A | B5: Brazil | M5: G | N5: France
A6: B | B6: England | M6: H | N6: Germany
A7: C | B7: Spain | M7: I | N7: Argentina
A8: D | B8: Mexico | M8: J | N8: Netherlands
A9: E | B9: Portugal | M9: K | N9: Canada
A10: F | B10: USA | M10: L | N10: Scotland
B12: 0.4375 | C12: Brazil vs England | E12: 0.45833333 | F12: Brazil vs Spain | H12: 0.47916667 | I12: Brazil vs Mexico | N12: 0.4375 | O12: France vs Scotland | Q12: 0.45833333 | R12: France vs Netherlands | T12: 0.47916667 | U12: France vs Germany
B13: 0.4375 | C13: Spain vs Mexico | E13: 0.45833333 | F13: England vs Mexico | H13: 0.47916667 | I13: England vs Spain | N13: 0.4375 | O13: Germany vs Canada | Q13: 0.45833333 | R13: Canada vs Scotland | T13: 0.47916667 | U13: Argentina vs Scotland
B15: 0.44444444 | C15: Brazil vs Portugal | E15: 0.46527778 | F15: Brazil vs USA | H15: 0.48611111 | I15: Portugal vs USA | N15: 0.44444444 | O15: Argentina vs Netherlands | Q15: 0.46527778 | R15: France vs Argentina | T15: 0.48611111 | U15: Canada vs Netherlands
B16: 0.44444444 | C16: England vs USA | E16: 0.46527778 | F16: England vs Portugal | N16: 0.44444444 | O16: France vs Canada | Q16: 0.46527778 | R16: Germany vs Scotland
B18: 0.45138889 | C18: Spain vs Portugal | E18: 0.47222222 | F18: Spain vs USA | N18: 0.45138889 | O18: Germany vs Argentina | Q18: 0.47222222 | R18: Germany vs Netherlands
B19: 0.45138889 | C19: Mexico vs USA | E19: 0.47222222 | F19: Mexico vs Portugal | N19: 0.45138889 | O19: Netherlands vs Scotland | Q19: 0.47222222 | R19: Argentina vs Canada
B22: 0.49305556 | C22: England vs Brazil | E22: 0.55555556 | F22: Spain vs Brazil | H22: 0.57638889 | I22: Brazil vs Mexico | N22: 0.49305556 | O22: Scotland vs France | Q22: 0.55555556 | R22: Netherlands vs France | T22: 0.57638889 | U22: Germany vs France
B23: 0.49305556 | C23: Mexico vs Spain | E23: 0.55555556 | F23: Mexico vs England | H23: 0.57638889 | I23: Spain vs England | N23: 0.49305556 | O23: Canada vs Germany | Q23: 0.55555556 | R23: Scotland vs Canada | T23: 0.57638889 | U23: Scotland vs Argentina
B25: 0.54166667 | C25: Portugal vs Brazil | E25: 0.5625 | F25: USA vs Brazil | H25: 0.58333333 | I25: USA vs Portugal | N25: 0.54166667 | O25: Netherlands vs Argentina | Q25: 0.5625 | R25: Argentina vs France | T25: 0.58333333 | U25: Netherlands vs Canada
B26: 0.54166667 | C26: USA vs England | E26: 0.5625 | F26: Portugal vs England | N26: 0.54166667 | O26: Canada vs France | Q26: 0.5625 | R26: Scotland vs Germany
B28: 0.54861111 | C28: Portugal vs Spain | E28: 0.56944444 | F28: USA vs Spain | N28: 0.54861111 | O28: Argentina vs Germany | Q28: 0.56944444 | R28: Netherlands vs Germany
B29: 0.54861111 | C29: USA vs Mexico | E29: 0.56944444 | F29: Mexico vs Portugal | N29: 0.54861111 | O29: Scotland vs Netherlands | Q29: 0.56944444 | R29: Canada vs Argentina

Sheet U9-U10 Scores
A1: U9-U10 – Match Results
A2: Enter final scores in the YELLOW cells only (whole numbers, e.g. 2 and 1). Leave both blank until the match has been played — the League and Goalscorer sheets update automatically.
A4: Group | B4: Time | C4: Home Team | D4: Home Goals | E4: Away Goals | F4: Away Team
A5: Group 1 | B5: 0.4375 | C5: Brazil | F5: England
A6: Group 1 | B6: 0.4375 | C6: Spain | F6: Mexico
A7: Group 1 | B7: 0.44444444 | C7: Brazil | F7: Portugal
A8: Group 1 | B8: 0.44444444 | C8: England | F8: USA
A9: Group 1 | B9: 0.45138889 | C9: Spain | F9: Portugal
A10: Group 1 | B10: 0.45138889 | C10: Mexico | F10: USA
A11: Group 1 | B11: 0.45833333 | C11: Brazil | F11: Spain
A12: Group 1 | B12: 0.45833333 | C12: England | F12: Mexico
A13: Group 1 | B13: 0.46527778 | C13: Brazil | F13: USA
A14: Group 1 | B14: 0.46527778 | C14: England | F14: Portugal
A15: Group 1 | B15: 0.47222222 | C15: Spain | F15: USA
A16: Group 1 | B16: 0.47222222 | C16: Mexico | F16: Portugal
... A64: Group 2 | B64: 0.58333333 | C64: Netherlands | F64: Canada

Sheet U9-U10 League
A1: U9-U10 League Tables
A2: Updates automatically from the Scores sheet. Ranked by Points, then Goal Difference, then Goals For. Do not type in this sheet.
A4: Group 1
A5: Pos | B5: Team | C5: P | D5: W | E5: D | F5: L | G5: GF | H5: GA | I5: GD | J5: Pts
A6: 1 | B6: =INDEX($M$6:$M$11,$L6) -> Brazil | C6: =INDEX($N$6:$N$11,$L6) -> 0 | D6: =INDEX($O$6:$O$11,$L6) -> 0 | E6: =INDEX($P$6:$P$11,$L6) -> 0 | F6: =INDEX($Q$6:$Q$11,$L6) -> 0 | G6: =INDEX($R$6:$R$11,$L6) -> 0 | H6: =INDEX($S$6:$S$11,$L6) -> 0 | I6: =INDEX($T$6:$T$11,$L6) -> 0 | J6: =INDEX($U$6:$U$11,$L6) -> 0 | L6: =MATCH(LARGE($V$6:$V$11,ROW()-5),$V$6:$V$11,0) -> 1 | M6: Brazil | N6: =SUMPRODUCT(('U9-U10 Scores'!$C$5:$C$64=$M6)*('U9-U10 Scores'!$D$5:$D$64<>"")*('U9-U10 Scores'!$E$5:$E$64<>""))+SUMPRODUCT(('U9-U10 Scores'!$F$5:$F$64=$M6)*('U9-U10 Scores'!$D$5:$D$64<>"")*('U9-U10 Scores'!$E$5:$E$64<>"")) -> 0 | O6: =SUMPRODUCT(('U9-U10 Scores'!$C$5:$C$64=$M6)*('U9-U10 Scores'!$D$5:$D$64<>"")*('U9-U10 Scores'!$E$5:$E$64<>"")*('U9-U10 Scores'!$D$5:$D$64>'U9-U10 Scores'!$E$5:$E$64))+SUMPRODUCT(('U9-U10 Scores'!$F$5:$F$64=$M6)*('U9-U10 Scores'!$D$5:$D$64<>"")*('U9-U10 Scores'!$E$5:$E$64<>"")*('U9-U10 Scores'!$E$5:$E$64>'U9-U10 Scores'!$D$5:$D$64)) -> 0 | P6: =SUMPRODUCT((('U9-U10 Scores'!$C$5:$C$64=$M6)+('U9-U10 Scores'!$F$5:$F$64=$M6))*('U9-U10 Scores'!$D$5:$D$64<>"")*('U9-U10 Scores'!$E$5:$E$64<>"")*('U9-U10 Scores'!$D$5:$D$64='U9-U10 Scores'!$E$5:$E$64)) -> 0 | Q6: =$N6-$O6-$P6 -> 0 | R6: =SUMPRODUCT(('U9-U10 Scores'!$C$5:$C$64=$M6)*('U9-U10 Scores'!$D$5:$D$64<>"")*('U9-U10 Scores'!$E$5:$E$64<>"")*'U9-U10 Scores'!$D$5:$D$64)+SUMPRODUCT(('U9-U10 Scores'!$F$5:$F$64=$M6)*('U9-U10 Scores'!$D$5:$D$64<>"")*('U9-U10 Scores'!$E$5:$E$64<>"")*'U9-U10 Scores'!$E$5:$E$64) -> 0 | S6: =SUMPRODUCT(('U9-U10 Scores'!$C$5:$C$64=$M6)*('U9-U10 Scores'!$D$5:$D$64<>"")*('U9-U10 Scores'!$E$5:$E$64<>"")*'U9-U10 Scores'!$E$5:$E$64)+SUMPRODUCT(('U9-U10 Scores'!$F$5:$F$64=$M6)*('U9-U10 Scores'!$D$5:$D$64<>"")*('U9-U10 Scores'!$E$5:$E$64<>"")*'U9-U10 Scores'!$D$5:$D$64) -> 0 | T6: =$R6-$S6 -> 0 | U6: =3*$O6+$P6 -> 0 | V6: =$U6*1000000+($T6+500)*1000+$R6+(12-ROW())*0.01 -> 500000.06
A7: 2 | B7: =INDEX($M$6:$M$11,$L7) -> England | C7: =INDEX($N$6:$N$11,$L7) -> 0 | D7: =INDEX($O$6:$O$11,$L7) -> 0 | E7: =INDEX($P$6:$P$11,$L7) -> 0 | F7: =INDEX($Q$6:$Q$11,$L7) -> 0 | G7: =INDEX($R$6:$R$11,$L7) -> 0 | H7: =INDEX($S$6:$S$11,$L7) -> 0 | I7: =INDEX($T$6:$T$11,$L7) -> 0 | J7: =INDEX($U$6:$U$11,$L7) -> 0 | L7: =MATCH(LARGE($V$6:$V$11,ROW()-5),$V$6:$V$11,0) -> 2 | M7: England | N7: =SUMPRODUCT(('U9-U10 Scores'!$C$5:$C$64=$M7)*('U9-U10 Scores'!$D$5:$D$64<>"")*('U9-U10 Scores'!$E$5:$E$64<>""))+SUMPRODUCT(('U9-U10 Scores'!$F$5:$F$64=$M7)*('U9-U10 Scores'!$D$5:$D$64<>"")*('U9-U10 Scores'!$E$5:$E$64<>"")) -> 0 | O7: =SUMPRODUCT(('U9-U10 Scores'!$C$5:$C$64=$M7)*('U9-U10 Scores'!$D$5:$D$64<>"")*('U9-U10 Scores'!$E$5:$E$64<>"")*('U9-U10 Scores'!$D$5:$D$64>'U9-U10 Scores'!$E$5:$E$64))+SUMPRODUCT(('U9-U10 Scores'!$F$5:$F$64=$M7)*('U9-U10 Scores'!$D$5:$D$64<>"")*('U9-U10 Scores'!$E$5:$E$64<>"")*('U9-U10 Scores'!$E$5:$E$64>'U9-U10 Scores'!$D$5:$D$64)) -> 0 | P7: =SUMPRODUCT((('U9-U10 Scores'!$C$5:$C$64=$M7)+('U9-U10 Scores'!$F$5:$F$64=$M7))*('U9-U10 Scores'!$D$5:$D$64<>"")*('U9-U10 Scores'!$E$5:$E$64<>"")*('U9-U10 Scores'!$D$5:$D$64='U9-U10 Scores'!$E$5:$E$64)) -> 0 | Q7: =$N7-$O7-$P7 -> 0 | R7: =SUMPRODUCT(('U9-U10 Scores'!$C$5:$C$64=$M7)*('U9-U10 Scores'!$D$5:$D$64<>"")*('U9-U10 Scores'!$E$5:$E$64<>"")*'U9-U10 Scores'!$D$5:$D$64)+SUMPRODUCT(('U9-U10 Scores'!$F$5:$F$64=$M7)*('U9-U10 Scores'!$D$5:$D$64<>"")*('U9-U10 Scores'!$E$5:$E$64<>"")*'U9-U10 Scores'!$E$5:$E$64) -> 0 | S7: =SUMPRODUCT(('U9-U10 Scores'!$C$5:$C$64=$M7)*('U9-U10 Scores'!$D$5:$D$64<>"")*('U9-U10 Scores'!$E$5:$E$64<>"")*'U9-U10 Scores'!$E$5:$E$64)+SUMPRODUCT(('U9-U10 Scores'!$F$5:$F$64=$M7)*('U9-U10 Scores'!$D$5:$D$64<>"")*('U9-U10 Scores'!$E$5:$E$64<>"")*'U9-U10 Scores'!$D$5:$D$64) -> 0 | T7: =$R7-$S7 -> 0 | U7: =3*$O7+$P7 -> 0 | V7: =$U7*1000000+($T7+500)*1000+$R7+(12-ROW())*0.01 -> 500000.05
A8: 3 | B8: =INDEX($M$6:$M$11,$L8) -> Spain | C8: =INDEX($N$6:$N$11,$L8) -> 0 | D8: =INDEX($O$6:$O$11,$L8) -> 0 | E8: =INDEX($P$6:$P$11,$L8) -> 0 | F8: =INDEX($Q$6:$Q$11,$L8) -> 0 | G8: =INDEX($R$6:$R$11,$L8) -> 0 | H8: =INDEX($S$6:$S$11,$L8) -> 0 | I8: =INDEX($T$6:$T$11,$L8) -> 0 | J8: =INDEX($U$6:$U$11,$L8) -> 0 | L8: =MATCH(LARGE($V$6:$V$11,ROW()-5),$V$6:$V$11,0) -> 3 | M8: Spain | N8: =SUMPRODUCT(('U9-U10 Scores'!$C$5:$C$64=$M8)*('U9-U10 Scores'!$D$5:$D$64<>"")*('U9-U10 Scores'!$E$5:$E$64<>""))+SUMPRODUCT(('U9-U10 Scores'!$F$5:$F$64=$M8)*('U9-U10 Scores'!$D$5:$D$64<>"")*('U9-U10 Scores'!$E$5:$E$64<>"")) -> 0 | O8: =SUMPRODUCT(('U9-U10 Scores'!$C$5:$C$64=$M8)*('U9-U10 Scores'!$D$5:$D$64<>"")*('U9-U10 Scores'!$E$5:$E$64<>"")*('U9-U10 Scores'!$D$5:$D$64>'U9-U10 Scores'!$E$5:$E$64))+SUMPRODUCT(('U9-U10 Scores'!$F$5:$F$64=$M8)*('U9-U10 Scores'!$D$5:$D$64<>"")*('U9-U10 Scores'!$E$5:$E$64<>"")*('U9-U10 Scores'!$E$5:$E$64>'U9-U10 Scores'!$D$5:$D$64)) -> 0 | P8: =SUMPRODUCT((('U9-U10 Scores'!$C$5:$C$64=$M8)+('U9-U10 Scores'!$F$5:$F$64=$M8))*('U9-U10 Scores'!$D$5:$D$64<>"")*('U9-U10 Scores'!$E$5:$E$64<>"")*('U9-U10 Scores'!$D$5:$D$64='U9-U10 Scores'!$E$5:$E$64)) -> 0 | Q8: =$N8-$O8-$P8 -> 0 | R8: =SUMPRODUCT(('U9-U10 Scores'!$C$5:$C$64=$M8)*('U9-U10 Scores'!$D$5:$D$64<>"")*('U9-U10 Scores'!$E$5:$E$64<>"")*'U9-U10 Scores'!$D$5:$D$64)+SUMPRODUCT(('U9-U10 Scores'!$F$5:$F$64=$M8)*('U9-U10 Scores'!$D$5:$D$64<>"")*('U9-U10 Scores'!$E$5:$E$64<>"")*'U9-U10 Scores'!$E$5:$E$64) -> 0 | S8: =SUMPRODUCT(('U9-U10 Scores'!$C$5:$C$64=$M8)*('U9-U10 Scores'!$D$5:$D$64<>"")*('U9-U10 Scores'!$E$5:$E$64<>"")*'U9-U10 Scores'!$E$5:$E$64)+SUMPRODUCT(('U9-U10 Scores'!$F$5:$F$64=$M8)*('U9-U10 Scores'!$D$5:$D$64<>"")*('U9-U10 Scores'!$E$5:$E$64<>"")*'U9-U10 Scores'!$D$5:$D$64) -> 0 | T8: =$R8-$S8 -> 0 | U8: =3*$O8+$P8 -> 0 | V8: =$U8*1000000+($T8+500)*1000+$R8+(12-ROW())*0.01 -> 500000.04
A9: 4 | B9: =INDEX($M$6:$M$11,$L9) -> Mexico | C9: =INDEX($N$6:$N$11,$L9) -> 0 | D9: =INDEX($O$6:$O$11,$L9) -> 0 | E9: =INDEX($P$6:$P$11,$L9) -> 0 | F9: =INDEX($Q$6:$Q$11,$L9) -> 0 | G9: =INDEX($R$6:$R$11,$L9) -> 0 | H9: =INDEX($S$6:$S$11,$L9) -> 0 | I9: =INDEX($T$6:$T$11,$L9) -> 0 | J9: =INDEX($U$6:$U$11,$L9) -> 0 | L9: =MATCH(LARGE($V$6:$V$11,ROW()-5),$V$6:$V$11,0) -> 4 | M9: Mexico | N9: =SUMPRODUCT(('U9-U10 Scores'!$C$5:$C$64=$M9)*('U9-U10 Scores'!$D$5:$D$64<>"")*('U9-U10 Scores'!$E$5:$E$64<>""))+SUMPRODUCT(('U9-U10 Scores'!$F$5:$F$64=$M9)*('U9-U10 Scores'!$D$5:$D$64<>"")*('U9-U10 Scores'!$E$5:$E$64<>"")) -> 0 | O9: =SUMPRODUCT(('U9-U10 Scores'!$C$5:$C$64=$M9)*('U9-U10 Scores'!$D$5:$D$64<>"")*('U9-U10 Scores'!$E$5:$E$64<>"")*('U9-U10 Scores'!$D$5:$D$64>'U9-U10 Scores'!$E$5:$E$64))+SUMPRODUCT(('U9-U10 Scores'!$F$5:$F$64=$M9)*('U9-U10 Scores'!$D$5:$D$64<>"")*('U9-U10 Scores'!$E$5:$E$64<>"")*('U9-U10 Scores'!$E$5:$E$64>'U9-U10 Scores'!$D$5:$D$64)) -> 0 | P9: =SUMPRODUCT((('U9-U10 Scores'!$C$5:$C$64=$M9)+('U9-U10 Scores'!$F$5:$F$64=$M9))*('U9-U10 Scores'!$D$5:$D$64<>"")*('U9-U10 Scores'!$E$5:$E$64<>"")*('U9-U10 Scores'!$D$5:$D$64='U9-U10 Scores'!$E$5:$E$64)) -> 0 | Q9: =$N9-$O9-$P9 -> 0 | R9: =SUMPRODUCT(('U9-U10 Scores'!$C$5:$C$64=$M9)*('U9-U10 Scores'!$D$5:$D$64<>"")*('U9-U10 Scores'!$E$5:$E$64<>"")*'U9-U10 Scores'!$D$5:$D$64)+SUMPRODUCT(('U9-U10 Scores'!$F$5:$F$64=$M9)*('U9-U10 Scores'!$D$5:$D$64<>"")*('U9-U10 Scores'!$E$5:$E$64<>"")*'U9-U10 Scores'!$E$5:$E$64) -> 0 | S9: =SUMPRODUCT(('U9-U10 Scores'!$C$5:$C$64=$M9)*('U9-U10 Scores'!$D$5:$D$64<>"")*('U9-U10 Scores'!$E$5:$E$64<>"")*'U9-U10 Scores'!$E$5:$E$64)+SUMPRODUCT(('U9-U10 Scores'!$F$5:$F$64=$M9)*('U9-U10 Scores'!$D$5:$D$64<>"")*('U9-U10 Scores'!$E$5:$E$64<>"")*'U9-U10 Scores'!$D$5:$D$64) -> 0 | T9: =$R9-$S9 -> 0 | U9: =3*$O9+$P9 -> 0 | V9: =$U9*1000000+($T9+500)*1000+$R9+(12-ROW())*0.01 -> 500000.03
A10: 5 | B10: =INDEX($M$6:$M$11,$L10) -> Portugal | C10: =INDEX($N$6:$N$11,$L10) -> 0 | D10: =INDEX($O$6:$O$11,$L10) -> 0 | E10: =INDEX($P$6:$P$11,$L10) -> 0 | F10: =INDEX($Q$6:$Q$11,$L10) -> 0 | G10: =INDEX($R$6:$R$11,$L10) -> 0 | H10: =INDEX($S$6:$S$11,$L10) -> 0 | I10: =INDEX($T$6:$T$11,$L10) -> 0 | J10: =INDEX($U$6:$U$11,$L10) -> 0 | L10: =MATCH(LARGE($V$6:$V$11,ROW()-5),$V$6:$V$11,0) -> 5 | M10: Portugal | N10: =SUMPRODUCT(('U9-U10 Scores'!$C$5:$C$64=$M10)*('U9-U10 Scores'!$D$5:$D$64<>"")*('U9-U10 Scores'!$E$5:$E$64<>""))+SUMPRODUCT(('U9-U10 Scores'!$F$5:$F$64=$M10)*('U9-U10 Scores'!$D$5:$D$64<>"")*('U9-U10 Scores'!$E$5:$E$64<>"")) -> 0 | O10: =SUMPRODUCT(('U9-U10 Scores'!$C$5:$C$64=$M10)*('U9-U10 Scores'!$D$5:$D$64<>"")*('U9-U10 Scores'!$E$5:$E$64<>"")*('U9-U10 Scores'!$D$5:$D$64>'U9-U10 Scores'!$E$5:$E$64))+SUMPRODUCT(('U9-U10 Scores'!$F$5:$F$64=$M10)*('U9-U10 Scores'!$D$5:$D$64<>"")*('U9-U10 Scores'!$E$5:$E$64<>"")*('U9-U10 Scores'!$E$5:$E$64>'U9-U10 Scores'!$D$5:$D$64)) -> 0 | P10: =SUMPRODUCT((('U9-U10 Scores'!$C$5:$C$64=$M10)+('U9-U10 Scores'!$F$5:$F$64=$M10))*('U9-U10 Scores'!$D$5:$D$64<>"")*('U9-U10 Scores'!$E$5:$E$64<>"")*('U9-U10 Scores'!$D$5:$D$64='U9-U10 Scores'!$E$5:$E$64)) -> 0 | Q10: =$N10-$O10-$P10 -> 0 | R10: =SUMPRODUCT(('U9-U10 Scores'!$C$5:$C$64=$M10)*('U9-U10 Scores'!$D$5:$D$64<>"")*('U9-U10 Scores'!$E$5:$E$64<>"")*'U9-U10 Scores'!$D$5:$D$64)+SUMPRODUCT(('U9-U10 Scores'!$F$5:$F$64=$M10)*('U9-U10 Scores'!$D$5:$D$64<>"")*('U9-U10 Scores'!$E$5:$E$64<>"")*'U9-U10 Scores'!$E$5:$E$64) -> 0 | S10: =SUMPRODUCT(('U9-U10 Scores'!$C$5:$C$64=$M10)*('U9-U10 Scores'!$D$5:$D$64<>"")*('U9-U10 Scores'!$E$5:$E$64<>"")*'U9-U10 Scores'!$E$5:$E$64)+SUMPRODUCT(('U9-U10 Scores'!$F$5:$F$64=$M10)*('U9-U10 Scores'!$D$5:$D$64<>"")*('U9-U10 Scores'!$E$5:$E$64<>"")*'U9-U10 Scores'!$D$5:$D$64) -> 0 | T10: =$R10-$S10 -> 0 | U10: =3*$O10+$P10 -> 0 | V10: =$U10*1000000+($T10+500)*1000+$R10+(12-ROW())*0.01 -> 500000.02
A11: 6 | B11: =INDEX($M$6:$M$11,$L11) -> USA | C11: =INDEX($N$6:$N$11,$L11) -> 0 | D11: =INDEX($O$6:$O$11,$L11) -> 0 | E11: =INDEX($P$6:$P$11,$L11) -> 0 | F11: =INDEX($Q$6:$Q$11,$L11) -> 0 | G11: =INDEX($R$6:$R$11,$L11) -> 0 | H11: =INDEX($S$6:$S$11,$L11) -> 0 | I11: =INDEX($T$6:$T$11,$L11) -> 0 | J11: =INDEX($U$6:$U$11,$L11) -> 0 | L11: =MATCH(LARGE($V$6:$V$11,ROW()-5),$V$6:$V$11,0) -> 6 | M11: USA | N11: =SUMPRODUCT(('U9-U10 Scores'!$C$5:$C$64=$M11)*('U9-U10 Scores'!$D$5:$D$64<>"")*('U9-U10 Scores'!$E$5:$E$64<>""))+SUMPRODUCT(('U9-U10 Scores'!$F$5:$F$64=$M11)*('U9-U10 Scores'!$D$5:$D$64<>"")*('U9-U10 Scores'!$E$5:$E$64<>"")) -> 0 | O11: =SUMPRODUCT(('U9-U10 Scores'!$C$5:$C$64=$M11)*('U9-U10 Scores'!$D$5:$D$64<>"")*('U9-U10 Scores'!$E$5:$E$64<>"")*('U9-U10 Scores'!$D$5:$D$64>'U9-U10 Scores'!$E$5:$E$64))+SUMPRODUCT(('U9-U10 Scores'!$F$5:$F$64=$M11)*('U9-U10 Scores'!$D$5:$D$64<>"")*('U9-U10 Scores'!$E$5:$E$64<>"")*('U9-U10 Scores'!$E$5:$E$64>'U9-U10 Scores'!$D$5:$D$64)) -> 0 | P11: =SUMPRODUCT((('U9-U10 Scores'!$C$5:$C$64=$M11)+('U9-U10 Scores'!$F$5:$F$64=$M11))*('U9-U10 Scores'!$D$5:$D$64<>"")*('U9-U10 Scores'!$E$5:$E$64<>"")*('U9-U10 Scores'!$D$5:$D$64='U9-U10 Scores'!$E$5:$E$64)) -> 0 | Q11: =$N11-$O11-$P11 -> 0 | R11: =SUMPRODUCT(('U9-U10 Scores'!$C$5:$C$64=$M11)*('U9-U10 Scores'!$D$5:$D$64<>"")*('U9-U10 Scores'!$E$5:$E$64<>"")*'U9-U10 Scores'!$D$5:$D$64)+SUMPRODUCT(('U9-U10 Scores'!$F$5:$F$64=$M11)*('U9-U10 Scores'!$D$5:$D$64<>"")*('U9-U10 Scores'!$E$5:$E$64<>"")*'U9-U10 Scores'!$E$5:$E$64) -> 0 | S11: =SUMPRODUCT(('U9-U10 Scores'!$C$5:$C$64=$M11)*('U9-U10 Scores'!$D$5:$D$64<>"")*('U9-U10 Scores'!$E$5:$E$64<>"")*'U9-U10 Scores'!$E$5:$E$64)+SUMPRODUCT(('U9-U10 Scores'!$F$5:$F$64=$M11)*('U9-U10 Scores'!$D$5:$D$64<>"")*('U9-U10 Scores'!$E$5:$E$64<>"")*'U9-U10 Scores'!$D$5:$D$64) -> 0 | T11: =$R11-$S11 -> 0 | U11: =3*$O11+$P11 -> 0 | V11: =$U11*1000000+($T11+500)*1000+$R11+(12-ROW())*0.01 -> 500000.01
A14: Group 2
A15: Pos | B15: Team | C15: P | D15: W | E15: D | F15: L | G15: GF | H15: GA | I15: GD | J15: Pts
A16: 1 | B16: =INDEX($M$16:$M$21,$L16) -> France | C16: =INDEX($N$16:$N$21,$L16) -> 0 | D16: =INDEX($O$16:$O$21,$L16) -> 0 | E16: =INDEX($P$16:$P$21,$L16) -> 0 | F16: =INDEX($Q$16:$Q$21,$L16) -> 0 | G16: =INDEX($R$16:$R$21,$L16) -> 0 | H16: =INDEX($S$16:$S$21,$L16) -> 0 | I16: =INDEX($T$16:$T$21,$L16) -> 0 | J16: =INDEX($U$16:$U$21,$L16) -> 0 | L16: =MATCH(LARGE($V$16:$V$21,ROW()-15),$V$16:$V$21,0) -> 1 | M16: France | N16: =SUMPRODUCT(('U9-U10 Scores'!$C$5:$C$64=$M16)*('U9-U10 Scores'!$D$5:$D$64<>"")*('U9-U10 Scores'!$E$5:$E$64<>""))+SUMPRODUCT(('U9-U10 Scores'!$F$5:$F$64=$M16)*('U9-U10 Scores'!$D$5:$D$64<>"")*('U9-U10 Scores'!$E$5:$E$64<>"")) -> 0 | O16: =SUMPRODUCT(('U9-U10 Scores'!$C$5:$C$64=$M16)*('U9-U10 Scores'!$D$5:$D$64<>"")*('U9-U10 Scores'!$E$5:$E$64<>"")*('U9-U10 Scores'!$D$5:$D$64>'U9-U10 Scores'!$E$5:$E$64))+SUMPRODUCT(('U9-U10 Scores'!$F$5:$F$64=$M16)*('U9-U10 Scores'!$D$5:$D$64<>"")*('U9-U10 Scores'!$E$5:$E$64<>"")*('U9-U10 Scores'!$E$5:$E$64>'U9-U10 Scores'!$D$5:$D$64)) -> 0 | P16: =SUMPRODUCT((('U9-U10 Scores'!$C$5:$C$64=$M16)+('U9-U10 Scores'!$F$5:$F$64=$M16))*('U9-U10 Scores'!$D$5:$D$64<>"")*('U9-U10 Scores'!$E$5:$E$64<>"")*('U9-U10 Scores'!$D$5:$D$64='U9-U10 Scores'!$E$5:$E$64)) -> 0 | Q16: =$N16-$O16-$P16 -> 0 | R16: =SUMPRODUCT(('U9-U10 Scores'!$C$5:$C$64=$M16)*('U9-U10 Scores'!$D$5:$D$64<>"")*('U9-U10 Scores'!$E$5:$E$64<>"")*'U9-U10 Scores'!$D$5:$D$64)+SUMPRODUCT(('U9-U10 Scores'!$F$5:$F$64=$M16)*('U9-U10 Scores'!$D$5:$D$64<>"")*('U9-U10 Scores'!$E$5:$E$64<>"")*'U9-U10 Scores'!$E$5:$E$64) -> 0 | S16: =SUMPRODUCT(('U9-U10 Scores'!$C$5:$C$64=$M16)*('U9-U10 Scores'!$D$5:$D$64<>"")*('U9-U10 Scores'!$E$5:$E$64<>"")*'U9-U10 Scores'!$E$5:$E$64)+SUMPRODUCT(('U9-U10 Scores'!$F$5:$F$64=$M16)*('U9-U10 Scores'!$D$5:$D$64<>"")*('U9-U10 Scores'!$E$5:$E$64<>"")*'U9-U10 Scores'!$D$5:$D$64) -> 0 | T16: =$R16-$S16 -> 0 | U16: =3*$O16+$P16 -> 0 | V16: =$U16*1000000+($T16+500)*1000+$R16+(22-ROW())*0.01 -> 500000.06
A17: 2 | B17: =INDEX($M$16:$M$21,$L17) -> Germany | C17: =INDEX($N$16:$N$21,$L17) -> 0 | D17: =INDEX($O$16:$O$21,$L17) -> 0 | E17: =INDEX($P$16:$P$21,$L17) -> 0 | F17: =INDEX($Q$16:$Q$21,$L17) -> 0 | G17: =INDEX($R$16:$R$21,$L17) -> 0 | H17: =INDEX($S$16:$S$21,$L17) -> 0 | I17: =INDEX($T$16:$T$21,$L17) -> 0 | J17: =INDEX($U$16:$U$21,$L17) -> 0 | L17: =MATCH(LARGE($V$16:$V$21,ROW()-15),$V$16:$V$21,0) -> 2 | M17: Germany | N17: =SUMPRODUCT(('U9-U10 Scores'!$C$5:$C$64=$M17)*('U9-U10 Scores'!$D$5:$D$64<>"")*('U9-U10 Scores'!$E$5:$E$64<>""))+SUMPRODUCT(('U9-U10 Scores'!$F$5:$F$64=$M17)*('U9-U10 Scores'!$D$5:$D$64<>"")*('U9-U10 Scores'!$E$5:$E$64<>"")) -> 0 | O17: =SUMPRODUCT(('U9-U10 Scores'!$C$5:$C$64=$M17)*('U9-U10 Scores'!$D$5:$D$64<>"")*('U9-U10 Scores'!$E$5:$E$64<>"")*('U9-U10 Scores'!$D$5:$D$64>'U9-U10 Scores'!$E$5:$E$64))+SUMPRODUCT(('U9-U10 Scores'!$F$5:$F$64=$M17)*('U9-U10 Scores'!$D$5:$D$64<>"")*('U9-U10 Scores'!$E$5:$E$64<>"")*('U9-U10 Scores'!$E$5:$E$64>'U9-U10 Scores'!$D$5:$D$64)) -> 0 | P17: =SUMPRODUCT((('U9-U10 Scores'!$C$5:$C$64=$M17)+('U9-U10 Scores'!$F$5:$F$64=$M17))*('U9-U10 Scores'!$D$5:$D$64<>"")*('U9-U10 Scores'!$E$5:$E$64<>"")*('U9-U10 Scores'!$D$5:$D$64='U9-U10 Scores'!$E$5:$E$64)) -> 0 | Q17: =$N17-$O17-$P17 -> 0 | R17: =SUMPRODUCT(('U9-U10 Scores'!$C$5:$C$64=$M17)*('U9-U10 Scores'!$D$5:$D$64<>"")*('U9-U10 Scores'!$E$5:$E$64<>"")*'U9-U10 Scores'!$D$5:$D$64)+SUMPRODUCT(('U9-U10 Scores'!$F$5:$F$64=$M17)*('U9-U10 Scores'!$D$5:$D$64<>"")*('U9-U10 Scores'!$E$5:$E$64<>"")*'U9-U10 Scores'!$E$5:$E$64) -> 0 | S17: =SUMPRODUCT(('U9-U10 Scores'!$C$5:$C$64=$M17)*('U9-U10 Scores'!$D$5:$D$64<>"")*('U9-U10 Scores'!$E$5:$E$64<>"")*'U9-U10 Scores'!$E$5:$E$64)+SUMPRODUCT(('U9-U10 Scores'!$F$5:$F$64=$M17)*('U9-U10 Scores'!$D$5:$D$64<>"")*('U9-U10 Scores'!$E$5:$E$64<>"")*'U9-U10 Scores'!$D$5:$D$64) -> 0 | T17: =$R17-$S17 -> 0 | U17: =3*$O17+$P17 -> 0 | V17: =$U17*1000000+($T17+500)*1000+$R17+(22-ROW())*0.01 -> 500000.05
A18: 3 | B18: =INDEX($M$16:$M$21,$L18) -> Argentina | C18: =INDEX($N$16:$N$21,$L18) -> 0 | D18: =INDEX($O$16:$O$21,$L18) -> 0 | E18: =INDEX($P$16:$P$21,$L18) -> 0 | F18: =INDEX($Q$16:$Q$21,$L18) -> 0 | G18: =INDEX($R$16:$R$21,$L18) -> 0 | H18: =INDEX($S$16:$S$21,$L18) -> 0 | I18: =INDEX($T$16:$T$21,$L18) -> 0 | J18: =INDEX($U$16:$U$21,$L18) -> 0 | L18: =MATCH(LARGE($V$16:$V$21,ROW()-15),$V$16:$V$21,0) -> 3 | M18: Argentina | N18: =SUMPRODUCT(('U9-U10 Scores'!$C$5:$C$64=$M18)*('U9-U10 Scores'!$D$5:$D$64<>"")*('U9-U10 Scores'!$E$5:$E$64<>""))+SUMPRODUCT(('U9-U10 Scores'!$F$5:$F$64=$M18)*('U9-U10 Scores'!$D$5:$D$64<>"")*('U9-U10 Scores'!$E$5:$E$64<>"")) -> 0 | O18: =SUMPRODUCT(('U9-U10 Scores'!$C$5:$C$64=$M18)*('U9-U10 Scores'!$D$5:$D$64<>"")*('U9-U10 Scores'!$E$5:$E$64<>"")*('U9-U10 Scores'!$D$5:$D$64>'U9-U10 Scores'!$E$5:$E$64))+SUMPRODUCT(('U9-U10 Scores'!$F$5:$F$64=$M18)*('U9-U10 Scores'!$D$5:$D$64<>"")*('U9-U10 Scores'!$E$5:$E$64<>"")*('U9-U10 Scores'!$E$5:$E$64>'U9-U10 Scores'!$D$5:$D$64)) -> 0 | P18: =SUMPRODUCT((('U9-U10 Scores'!$C$5:$C$64=$M18)+('U9-U10 Scores'!$F$5:$F$64=$M18))*('U9-U10 Scores'!$D$5:$D$64<>"")*('U9-U10 Scores'!$E$5:$E$64<>"")*('U9-U10 Scores'!$D$5:$D$64='U9-U10 Scores'!$E$5:$E$64)) -> 0 | Q18: =$N18-$O18-$P18 -> 0 | R18: =SUMPRODUCT(('U9-U10 Scores'!$C$5:$C$64=$M18)*('U9-U10 Scores'!$D$5:$D$64<>"")*('U9-U10 Scores'!$E$5:$E$64<>"")*'U9-U10 Scores'!$D$5:$D$64)+SUMPRODUCT(('U9-U10 Scores'!$F$5:$F$64=$M18)*('U9-U10 Scores'!$D$5:$D$64<>"")*('U9-U10 Scores'!$E$5:$E$64<>"")*'U9-U10 Scores'!$E$5:$E$64) -> 0 | S18: =SUMPRODUCT(('U9-U10 Scores'!$C$5:$C$64=$M18)*('U9-U10 Scores'!$D$5:$D$64<>"")*('U9-U10 Scores'!$E$5:$E$64<>"")*'U9-U10 Scores'!$E$5:$E$64)+SUMPRODUCT(('U9-U10 Scores'!$F$5:$F$64=$M18)*('U9-U10 Scores'!$D$5:$D$64<>"")*('U9-U10 Scores'!$E$5:$E$64<>"")*'U9-U10 Scores'!$D$5:$D$64) -> 0 | T18: =$R18-$S18 -> 0 | U18: =3*$O18+$P18 -> 0 | V18: =$U18*1000000+($T18+500)*1000+$R18+(22-ROW())*0.01 -> 500000.04
A19: 4 | B19: =INDEX($M$16:$M$21,$L19) -> Netherlands | C19: =INDEX($N$16:$N$21,$L19) -> 0 | D19: =INDEX($O$16:$O$21,$L19) -> 0 | E19: =INDEX($P$16:$P$21,$L19) -> 0 | F19: =INDEX($Q$16:$Q$21,$L19) -> 0 | G19: =INDEX($R$16:$R$21,$L19) -> 0 | H19: =INDEX($S$16:$S$21,$L19) -> 0 | I19: =INDEX($T$16:$T$21,$L19) -> 0 | J19: =INDEX($U$16:$U$21,$L19) -> 0 | L19: =MATCH(LARGE($V$16:$V$21,ROW()-15),$V$16:$V$21,0) -> 4 | M19: Netherlands | N19: =SUMPRODUCT(('U9-U10 Scores'!$C$5:$C$64=$M19)*('U9-U10 Scores'!$D$5:$D$64<>"")*('U9-U10 Scores'!$E$5:$E$64<>""))+SUMPRODUCT(('U9-U10 Scores'!$F$5:$F$64=$M19)*('U9-U10 Scores'!$D$5:$D$64<>"")*('U9-U10 Scores'!$E$5:$E$64<>"")) -> 0 | O19: =SUMPRODUCT(('U9-U10 Scores'!$C$5:$C$64=$M19)*('U9-U10 Scores'!$D$5:$D$64<>"")*('U9-U10 Scores'!$E$5:$E$64<>"")*('U9-U10 Scores'!$D$5:$D$64>'U9-U10 Scores'!$E$5:$E$64))+SUMPRODUCT(('U9-U10 Scores'!$F$5:$F$64=$M19)*('U9-U10 Scores'!$D$5:$D$64<>"")*('U9-U10 Scores'!$E$5:$E$64<>"")*('U9-U10 Scores'!$E$5:$E$64>'U9-U10 Scores'!$D$5:$D$64)) -> 0 | P19: =SUMPRODUCT((('U9-U10 Scores'!$C$5:$C$64=$M19)+('U9-U10 Scores'!$F$5:$F$64=$M19))*('U9-U10 Scores'!$D$5:$D$64<>"")*('U9-U10 Scores'!$E$5:$E$64<>"")*('U9-U10 Scores'!$D$5:$D$64='U9-U10 Scores'!$E$5:$E$64)) -> 0 | Q19: =$N19-$O19-$P19 -> 0 | R19: =SUMPRODUCT(('U9-U10 Scores'!$C$5:$C$64=$M19)*('U9-U10 Scores'!$D$5:$D$64<>"")*('U9-U10 Scores'!$E$5:$E$64<>"")*'U9-U10 Scores'!$D$5:$D$64)+SUMPRODUCT(('U9-U10 Scores'!$F$5:$F$64=$M19)*('U9-U10 Scores'!$D$5:$D$64<>"")*('U9-U10 Scores'!$E$5:$E$64<>"")*'U9-U10 Scores'!$E$5:$E$64) -> 0 | S19: =SUMPRODUCT(('U9-U10 Scores'!$C$5:$C$64=$M19)*('U9-U10 Scores'!$D$5:$D$64<>"")*('U9-U10 Scores'!$E$5:$E$64<>"")*'U9-U10 Scores'!$E$5:$E$64)+SUMPRODUCT(('U9-U10 Scores'!$F$5:$F$64=$M19)*('U9-U10 Scores'!$D$5:$D$64<>"")*('U9-U10 Scores'!$E$5:$E$64<>"")*'U9-U10 Scores'!$D$5:$D$64) -> 0 | T19: =$R19-$S19 -> 0 | U19: =3*$O19+$P19 -> 0 | V19: =$U19*1000000+($T19+500)*1000+$R19+(22-ROW())*0.01 -> 500000.03
A20: 5 | B20: =INDEX($M$16:$M$21,$L20) -> Canada | C20: =INDEX($N$16:$N$21,$L20) -> 0 | D20: =INDEX($O$16:$O$21,$L20) -> 0 | E20: =INDEX($P$16:$P$21,$L20) -> 0 | F20: =INDEX($Q$16:$Q$21,$L20) -> 0 | G20: =INDEX($R$16:$R$21,$L20) -> 0 | H20: =INDEX($S$16:$S$21,$L20) -> 0 | I20: =INDEX($T$16:$T$21,$L20) -> 0 | J20: =INDEX($U$16:$U$21,$L20) -> 0 | L20: =MATCH(LARGE($V$16:$V$21,ROW()-15),$V$16:$V$21,0) -> 5 | M20: Canada | N20: =SUMPRODUCT(('U9-U10 Scores'!$C$5:$C$64=$M20)*('U9-U10 Scores'!$D$5:$D$64<>"")*('U9-U10 Scores'!$E$5:$E$64<>""))+SUMPRODUCT(('U9-U10 Scores'!$F$5:$F$64=$M20)*('U9-U10 Scores'!$D$5:$D$64<>"")*('U9-U10 Scores'!$E$5:$E$64<>"")) -> 0 | O20: =SUMPRODUCT(('U9-U10 Scores'!$C$5:$C$64=$M20)*('U9-U10 Scores'!$D$5:$D$64<>"")*('U9-U10 Scores'!$E$5:$E$64<>"")*('U9-U10 Scores'!$D$5:$D$64>'U9-U10 Scores'!$E$5:$E$64))+SUMPRODUCT(('U9-U10 Scores'!$F$5:$F$64=$M20)*('U9-U10 Scores'!$D$5:$D$64<>"")*('U9-U10 Scores'!$E$5:$E$64<>"")*('U9-U10 Scores'!$E$5:$E$64>'U9-U10 Scores'!$D$5:$D$64)) -> 0 | P20: =SUMPRODUCT((('U9-U10 Scores'!$C$5:$C$64=$M20)+('U9-U10 Scores'!$F$5:$F$64=$M20))*('U9-U10 Scores'!$D$5:$D$64<>"")*('U9-U10 Scores'!$E$5:$E$64<>"")*('U9-U10 Scores'!$D$5:$D$64='U9-U10 Scores'!$E$5:$E$64)) -> 0 | Q20: =$N20-$O20-$P20 -> 0 | R20: =SUMPRODUCT(('U9-U10 Scores'!$C$5:$C$64=$M20)*('U9-U10 Scores'!$D$5:$D$64<>"")*('U9-U10 Scores'!$E$5:$E$64<>"")*'U9-U10 Scores'!$D$5:$D$64)+SUMPRODUCT(('U9-U10 Scores'!$F$5:$F$64=$M20)*('U9-U10 Scores'!$D$5:$D$64<>"")*('U9-U10 Scores'!$E$5:$E$64<>"")*'U9-U10 Scores'!$E$5:$E$64) -> 0 | S20: =SUMPRODUCT(('U9-U10 Scores'!$C$5:$C$64=$M20)*('U9-U10 Scores'!$D$5:$D$64<>"")*('U9-U10 Scores'!$E$5:$E$64<>"")*'U9-U10 Scores'!$E$5:$E$64)+SUMPRODUCT(('U9-U10 Scores'!$F$5:$F$64=$M20)*('U9-U10 Scores'!$D$5:$D$64<>"")*('U9-U10 Scores'!$E$5:$E$64<>"")*'U9-U10 Scores'!$D$5:$D$64) -> 0 | T20: =$R20-$S20 -> 0 | U20: =3*$O20+$P20 -> 0 | V20: =$U20*1000000+($T20+500)*1000+$R20+(22-ROW())*0.01 -> 500000.02
A21: 6 | B21: =INDEX($M$16:$M$21,$L21) -> Scotland | C21: =INDEX($N$16:$N$21,$L21) -> 0 | D21: =INDEX($O$16:$O$21,$L21) -> 0 | E21: =INDEX($P$16:$P$21,$L21) -> 0 | F21: =INDEX($Q$16:$Q$21,$L21) -> 0 | G21: =INDEX($R$16:$R$21,$L21) -> 0 | H21: =INDEX($S$16:$S$21,$L21) -> 0 | I21: =INDEX($T$16:$T$21,$L21) -> 0 | J21: =INDEX($U$16:$U$21,$L21) -> 0 | L21: =MATCH(LARGE($V$16:$V$21,ROW()-15),$V$16:$V$21,0) -> 6 | M21: Scotland | N21: =SUMPRODUCT(('U9-U10 Scores'!$C$5:$C$64=$M21)*('U9-U10 Scores'!$D$5:$D$64<>"")*('U9-U10 Scores'!$E$5:$E$64<>""))+SUMPRODUCT(('U9-U10 Scores'!$F$5:$F$64=$M21)*('U9-U10 Scores'!$D$5:$D$64<>"")*('U9-U10 Scores'!$E$5:$E$64<>"")) -> 0 | O21: =SUMPRODUCT(('U9-U10 Scores'!$C$5:$C$64=$M21)*('U9-U10 Scores'!$D$5:$D$64<>"")*('U9-U10 Scores'!$E$5:$E$64<>"")*('U9-U10 Scores'!$D$5:$D$64>'U9-U10 Scores'!$E$5:$E$64))+SUMPRODUCT(('U9-U10 Scores'!$F$5:$F$64=$M21)*('U9-U10 Scores'!$D$5:$D$64<>"")*('U9-U10 Scores'!$E$5:$E$64<>"")*('U9-U10 Scores'!$E$5:$E$64>'U9-U10 Scores'!$D$5:$D$64)) -> 0 | P21: =SUMPRODUCT((('U9-U10 Scores'!$C$5:$C$64=$M21)+('U9-U10 Scores'!$F$5:$F$64=$M21))*('U9-U10 Scores'!$D$5:$D$64<>"")*('U9-U10 Scores'!$E$5:$E$64<>"")*('U9-U10 Scores'!$D$5:$D$64='U9-U10 Scores'!$E$5:$E$64)) -> 0 | Q21: =$N21-$O21-$P21 -> 0 | R21: =SUMPRODUCT(('U9-U10 Scores'!$C$5:$C$64=$M21)*('U9-U10 Scores'!$D$5:$D$64<>"")*('U9-U10 Scores'!$E$5:$E$64<>"")*'U9-U10 Scores'!$D$5:$D$64)+SUMPRODUCT(('U9-U10 Scores'!$F$5:$F$64=$M21)*('U9-U10 Scores'!$D$5:$D$64<>"")*('U9-U10 Scores'!$E$5:$E$64<>"")*'U9-U10 Scores'!$E$5:$E$64) -> 0 | S21: =SUMPRODUCT(('U9-U10 Scores'!$C$5:$C$64=$M21)*('U9-U10 Scores'!$D$5:$D$64<>"")*('U9-U10 Scores'!$E$5:$E$64<>"")*'U9-U10 Scores'!$E$5:$E$64)+SUMPRODUCT(('U9-U10 Scores'!$F$5:$F$64=$M21)*('U9-U10 Scores'!$D$5:$D$64<>"")*('U9-U10 Scores'!$E$5:$E$64<>"")*'U9-U10 Scores'!$D$5:$D$64) -> 0 | T21: =$R21-$S21 -> 0 | U21: =3*$O21+$P21 -> 0 | V21: =$U21*1000000+($T21+500)*1000+$R21+(22-ROW())*0.01 -> 500000.01

Sheet U9-U10 Goalscorers
A1: U9-U10 Golden Boot
A2: Every time a player scores, add ONE ROW to the yellow GOAL LOG below: player name + team (e.g. "Jack S." / "Brazil"). Scored twice? Add two rows. The TOP SCORERS table sorts itself automatically.
A3: Tip: keep each player's name spelled exactly the same every time (add a surname initial if two players share a first name).
A4: GOAL LOG | F4: TOP SCORERS (automatic)
A5: Player | B5: Team | F5: Rank | G5: Player | H5: Team | I5: Goals
D6: =IF($A6="","",IF(COUNTIF($A$6:$A6,$A6)=1,COUNTIF($A$6:$A$305,$A6)*10000+(9999-ROW()),"")) | F6: =IF($K6="","",ROW()-5) | G6: =IF($K6="","",INDEX($A$6:$A$305,MATCH($K6,$D$6:$D$305,0))) | H6: =IF($K6="","",INDEX($B$6:$B$305,MATCH($K6,$D$6:$D$305,0))) | I6: =IF($K6="","",INT($K6/10000)) | K6: =IFERROR(LARGE($D$6:$D$305,ROW()-5),"")
D7: =IF($A7="","",IF(COUNTIF($A$6:$A7,$A7)=1,COUNTIF($A$6:$A$305,$A7)*10000+(9999-ROW()),"")) | F7: =IF($K7="","",ROW()-5) | G7: =IF($K7="","",INDEX($A$6:$A$305,MATCH($K7,$D$6:$D$305,0))) | H7: =IF($K7="","",INDEX($B$6:$B$305,MATCH($K7,$D$6:$D$305,0))) | I7: =IF($K7="","",INT($K7/10000)) | K7: =IFERROR(LARGE($D$6:$D$305,ROW()-5),"")
D8: =IF($A8="","",IF(COUNTIF($A$6:$A8,$A8)=1,COUNTIF($A$6:$A$305,$A8)*10000+(9999-ROW()),"")) | F8: =IF($K8="","",ROW()-5) | G8: =IF($K8="","",INDEX($A$6:$A$305,MATCH($K8,$D$6:$D$305,0))) | H8: =IF($K8="","",INDEX($B$6:$B$305,MATCH($K8,$D$6:$D$305,0))) | I8: =IF($K8="","",INT($K8/10000)) | K8: =IFERROR(LARGE($D$6:$D$305,ROW()-5),"")
D9: =IF($A9="","",IF(COUNTIF($A$6:$A9,$A9)=1,COUNTIF($A$6:$A$305,$A9)*10000+(9999-ROW()),"")) | F9: =IF($K9="","",ROW()-5) | G9: =IF($K9="","",INDEX($A$6:$A$305,MATCH($K9,$D$6:$D$305,0))) | H9: =IF($K9="","",INDEX($B$6:$B$305,MATCH($K9,$D$6:$D$305,0))) | I9: =IF($K9="","",INT($K9/10000)) | K9: =IFERROR(LARGE($D$6:$D$305,ROW()-5),"")
D10: =IF($A10="","",IF(COUNTIF($A$6:$A10,$A10)=1,COUNTIF($A$6:$A$305,$A10)*10000+(9999-ROW()),"")) | F10: =IF($K10="","",ROW()-5) | G10: =IF($K10="","",INDEX($A$6:$A$305,MATCH($K10,$D$6:$D$305,0))) | H10: =IF($K10="","",INDEX($B$6:$B$305,MATCH($K10,$D$6:$D$305,0))) | I10: =IF($K10="","",INT($K10/10000)) | K10: =IFERROR(LARGE($D$6:$D$305,ROW()-5),"")
D11: =IF($A11="","",IF(COUNTIF($A$6:$A11,$A11)=1,COUNTIF($A$6:$A$305,$A11)*10000+(9999-ROW()),"")) | F11: =IF($K11="","",ROW()-5) | G11: =IF($K11="","",INDEX($A$6:$A$305,MATCH($K11,$D$6:$D$305,0))) | H11: =IF($K11="","",INDEX($B$6:$B$305,MATCH($K11,$D$6:$D$305,0))) | I11: =IF($K11="","",INT($K11/10000)) | K11: =IFERROR(LARGE($D$6:$D$305,ROW()-5),"")
D12: =IF($A12="","",IF(COUNTIF($A$6:$A12,$A12)=1,COUNTIF($A$6:$A$305,$A12)*10000+(9999-ROW()),"")) | F12: =IF($K12="","",ROW()-5) | G12: =IF($K12="","",INDEX($A$6:$A$305,MATCH($K12,$D$6:$D$305,0))) | H12: =IF($K12="","",INDEX($B$6:$B$305,MATCH($K12,$D$6:$D$305,0))) | I12: =IF($K12="","",INT($K12/10000)) | K12: =IFERROR(LARGE($D$6:$D$305,ROW()-5),"")
D13: =IF($A13="","",IF(COUNTIF($A$6:$A13,$A13)=1,COUNTIF($A$6:$A$305,$A13)*10000+(9999-ROW()),"")) | F13: =IF($K13="","",ROW()-5) | G13: =IF($K13="","",INDEX($A$6:$A$305,MATCH($K13,$D$6:$D$305,0))) | H13: =IF($K13="","",INDEX($B$6:$B$305,MATCH($K13,$D$6:$D$305,0))) | I13: =IF($K13="","",INT($K13/10000)) | K13: =IFERROR(LARGE($D$6:$D$305,ROW()-5),"")
D14: =IF($A14="","",IF(COUNTIF($A$6:$A14,$A14)=1,COUNTIF($A$6:$A$305,$A14)*10000+(9999-ROW()),"")) | F14: =IF($K14="","",ROW()-5) | G14: =IF($K14="","",INDEX($A$6:$A$305,MATCH($K14,$D$6:$D$305,0))) | H14: =IF($K14="","",INDEX($B$6:$B$305,MATCH($K14,$D$6:$D$305,0))) | I14: =IF($K14="","",INT($K14/10000)) | K14: =IFERROR(LARGE($D$6:$D$305,ROW()-5),"")
D15: =IF($A15="","",IF(COUNTIF($A$6:$A15,$A15)=1,COUNTIF($A$6:$A$305,$A15)*10000+(9999-ROW()),"")) | F15: =IF($K15="","",ROW()-5) | G15: =IF($K15="","",INDEX($A$6:$A$305,MATCH($K15,$D$6:$D$305,0))) | H15: =IF($K15="","",INDEX($B$6:$B$305,MATCH($K15,$D$6:$D$305,0))) | I15: =IF($K15="","",INT($K15/10000)) | K15: =IFERROR(LARGE($D$6:$D$305,ROW()-5),"")
D16: =IF($A16="","",IF(COUNTIF($A$6:$A16,$A16)=1,COUNTIF($A$6:$A$305,$A16)*10000+(9999-ROW()),"")) | F16: =IF($K16="","",ROW()-5) | G16: =IF($K16="","",INDEX($A$6:$A$305,MATCH($K16,$D$6:$D$305,0))) | H16: =IF($K16="","",INDEX($B$6:$B$305,MATCH($K16,$D$6:$D$305,0))) | I16: =IF($K16="","",INT($K16/10000)) | K16: =IFERROR(LARGE($D$6:$D$305,ROW()-5),"")
D17: =IF($A17="","",IF(COUNTIF($A$6:$A17,$A17)=1,COUNTIF($A$6:$A$305,$A17)*10000+(9999-ROW()),"")) | F17: =IF($K17="","",ROW()-5) | G17: =IF($K17="","",INDEX($A$6:$A$305,MATCH($K17,$D$6:$D$305,0))) | H17: =IF($K17="","",INDEX($B$6:$B$305,MATCH($K17,$D$6:$D$305,0))) | I17: =IF($K17="","",INT($K17/10000)) | K17: =IFERROR(LARGE($D$6:$D$305,ROW()-5),"")
... D25: =IF($A25="","",IF(COUNTIF($A$6:$A25,$A25)=1,COUNTIF($A$6:$A$305,$A25)*10000+(9999-ROW()),"")) | F25: =IF($K25="","",ROW()-5) | G25: =IF($K25="","",INDEX($A$6:$A$305,MATCH($K25,$D$6:$D$305,0))) | H25: =IF($K25="","",INDEX($B$6:$B$305,MATCH($K25,$D$6:$D$305,0))) | I25: =IF($K25="","",INT($K25/10000)) | K25: =IFERROR(LARGE($D$6:$D$305,ROW()-5),"")
D26: =IF($A26="","",IF(COUNTIF($A$6:$A26,$A26)=1,COUNTIF($A$6:$A$305,$A26)*10000+(9999-ROW()),""))
D27: =IF($A27="","",IF(COUNTIF($A$6:$A27,$A27)=1,COUNTIF($A$6:$A$305,$A27)*10000+(9999-ROW()),""))
D28: =IF($A28="","",IF(COUNTIF($A$6:$A28,$A28)=1,COUNTIF($A$6:$A$305,$A28)*10000+(9999-ROW()),""))
D29: =IF($A29="","",IF(COUNTIF($A$6:$A29,$A29)=1,COUNTIF($A$6:$A$305,$A29)*10000+(9999-ROW()),""))
D30: =IF($A30="","",IF(COUNTIF($A$6:$A30,$A30)=1,COUNTIF($A$6:$A$305,$A30)*10000+(9999-ROW()),""))
D31: =IF($A31="","",IF(COUNTIF($A$6:$A31,$A31)=1,COUNTIF($A$6:$A$305,$A31)*10000+(9999-ROW()),""))
D32: =IF($A32="","",IF(COUNTIF($A$6:$A32,$A32)=1,COUNTIF($A$6:$A$305,$A32)*10000+(9999-ROW()),""))
D33: =IF($A33="","",IF(COUNTIF($A$6:$A33,$A33)=1,COUNTIF($A$6:$A$305,$A33)*10000+(9999-ROW()),""))
D34: =IF($A34="","",IF(COUNTIF($A$6:$A34,$A34)=1,COUNTIF($A$6:$A$305,$A34)*10000+(9999-ROW()),""))
D35: =IF($A35="","",IF(COUNTIF($A$6:$A35,$A35)=1,COUNTIF($A$6:$A$305,$A35)*10000+(9999-ROW()),""))
D36: =IF($A36="","",IF(COUNTIF($A$6:$A36,$A36)=1,COUNTIF($A$6:$A$305,$A36)*10000+(9999-ROW()),""))
D37: =IF($A37="","",IF(COUNTIF($A$6:$A37,$A37)=1,COUNTIF($A$6:$A$305,$A37)*10000+(9999-ROW()),""))
... D305: =IF($A305="","",IF(COUNTIF($A$6:$A305,$A305)=1,COUNTIF($A$6:$A$305,$A305)*10000+(9999-ROW()),""))

Sheet U11-U12
A1: World Cup Tournament
B3: Group 1 | N3: Group 2
A5: A | B5: Brazil | M5: G | N5: France
A6: B | B6: Germany | M6: H | N6: England
A7: C | B7: Spain | M7: I | N7: Argentina
A8: D | B8: Netherlands | M8: J | N8: Mexico
A9: E | B9: Portugal | M9: K | N9: Canada
A10: F | B10: Scotland | M10: L | N10: USA
B12: 0.4375 | C12: Brazil vs Germany | E12: 0.45833333 | F12: Brazil vs Spain | H12: 0.47916667 | I12: Brazil vs Netherlands | N12: 0.4375 | O12: France vs USA | Q12: 0.45833333 | R12: France vs Mexico | T12: 0.47916667 | U12: France vs England
B13: 0.4375 | C13: Spain vs Netherlands | E13: 0.45833333 | F13: Germany vs Netherlands | H13: 0.47916667 | I13: Germany vs Spain | N13: 0.4375 | O13: England vs Canada | Q13: 0.45833333 | R13: Canada vs USA | T13: 0.47916667 | U13: Argentina vs USA
B15: 0.44444444 | C15: Brazil vs Portugal | E15: 0.46527778 | F15: Brazil vs Scotland | H15: 0.48611111 | I15: Portugal vs Scotland | N15: 0.44444444 | O15: Argentina vs Mexico | Q15: 0.46527778 | R15: France vs Argentina | T15: 0.48611111 | U15: Canada vs Mexico
B16: 0.44444444 | C16: Germany vs Scotland | E16: 0.46527778 | F16: Germany vs Portugal | N16: 0.44444444 | O16: France vs Canada | Q16: 0.46527778 | R16: England vs USA
B18: 0.45138889 | C18: Spain vs Portugal | E18: 0.47222222 | F18: Spain vs Scotland | N18: 0.45138889 | O18: England vs Argentina | Q18: 0.47222222 | R18: England vs Mexico
B19: 0.45138889 | C19: Netherlands vs Scotland | E19: 0.47222222 | F19: Netherlands vs Portugal | N19: 0.45138889 | O19: Mexico vs USA | Q19: 0.47222222 | R19: Argentina vs Canada
B22: 0.49305556 | C22: Germany vs Brazil | E22: 0.55555556 | F22: Spain vs Brazil | H22: 0.57638889 | I22: Brazil vs Netherlands | N22: 0.49305556 | O22: USA vs France | Q22: 0.55555556 | R22: Mexico vs France | T22: 0.57638889 | U22: England vs France
B23: 0.49305556 | C23: Netherlands vs Spain | E23: 0.55555556 | F23: Netherlands vs Germany | H23: 0.57638889 | I23: Spain vs Germany | N23: 0.49305556 | O23: Canada vs England | Q23: 0.55555556 | R23: USA vs Canada | T23: 0.57638889 | U23: USA vs Argentina
B25: 0.54166667 | C25: Portugal vs Brazil | E25: 0.5625 | F25: Scotland vs Brazil | H25: 0.58333333 | I25: Scotland vs Portugal | N25: 0.54166667 | O25: Mexico vs Argentina | Q25: 0.5625 | R25: Argentina vs France | T25: 0.58333333 | U25: Mexico vs Canada
B26: 0.54166667 | C26: Scotland vs Germany | E26: 0.5625 | F26: Portugal vs Germany | N26: 0.54166667 | O26: Canada vs France | Q26: 0.5625 | R26: USA vs England
B28: 0.54861111 | C28: Portugal vs Spain | E28: 0.56944444 | F28: Scotland vs Spain | N28: 0.54861111 | O28: Argentina vs England | Q28: 0.56944444 | R28: Mexico vs England
B29: 0.54861111 | C29: Scotland vs Netherlands | E29: 0.56944444 | F29: Netherlands vs Portugal | N29: 0.54861111 | O29: USA vs Mexico | Q29: 0.56944444 | R29: Canada vs Argentina

Sheet U11-U12 Scores
A1: U11-U12 – Match Results
A2: Enter final scores in the YELLOW cells only (whole numbers, e.g. 2 and 1). Leave both blank until the match has been played — the League and Goalscorer sheets update automatically.
A4: Group | B4: Time | C4: Home Team | D4: Home Goals | E4: Away Goals | F4: Away Team
A5: Group 1 | B5: 0.4375 | C5: Brazil | F5: Germany
A6: Group 1 | B6: 0.4375 | C6: Spain | F6: Netherlands
A7: Group 1 | B7: 0.44444444 | C7: Brazil | F7: Portugal
A8: Group 1 | B8: 0.44444444 | C8: Germany | F8: Scotland
A9: Group 1 | B9: 0.45138889 | C9: Spain | F9: Portugal
A10: Group 1 | B10: 0.45138889 | C10: Netherlands | F10: Scotland
A11: Group 1 | B11: 0.45833333 | C11: Brazil | F11: Spain
A12: Group 1 | B12: 0.45833333 | C12: Germany | F12: Netherlands
A13: Group 1 | B13: 0.46527778 | C13: Brazil | F13: Scotland
A14: Group 1 | B14: 0.46527778 | C14: Germany | F14: Portugal
A15: Group 1 | B15: 0.47222222 | C15: Spain | F15: Scotland
A16: Group 1 | B16: 0.47222222 | C16: Netherlands | F16: Portugal
... A64: Group 2 | B64: 0.58333333 | C64: Mexico | F64: Canada

Sheet U11-U12 League
A1: U11-U12 League Tables
A2: Updates automatically from the Scores sheet. Ranked by Points, then Goal Difference, then Goals For. Do not type in this sheet.
A4: Group 1
A5: Pos | B5: Team | C5: P | D5: W | E5: D | F5: L | G5: GF | H5: GA | I5: GD | J5: Pts
A6: 1 | B6: =INDEX($M$6:$M$11,$L6) -> Brazil | C6: =INDEX($N$6:$N$11,$L6) -> 0 | D6: =INDEX($O$6:$O$11,$L6) -> 0 | E6: =INDEX($P$6:$P$11,$L6) -> 0 | F6: =INDEX($Q$6:$Q$11,$L6) -> 0 | G6: =INDEX($R$6:$R$11,$L6) -> 0 | H6: =INDEX($S$6:$S$11,$L6) -> 0 | I6: =INDEX($T$6:$T$11,$L6) -> 0 | J6: =INDEX($U$6:$U$11,$L6) -> 0 | L6: =MATCH(LARGE($V$6:$V$11,ROW()-5),$V$6:$V$11,0) -> 1 | M6: Brazil | N6: =SUMPRODUCT(('U11-U12 Scores'!$C$5:$C$64=$M6)*('U11-U12 Scores'!$D$5:$D$64<>"")*('U11-U12 Scores'!$E$5:$E$64<>""))+SUMPRODUCT(('U11-U12 Scores'!$F$5:$F$64=$M6)*('U11-U12 Scores'!$D$5:$D$64<>"")*('U11-U12 Scores'!$E$5:$E$64<>"")) -> 0 | O6: =SUMPRODUCT(('U11-U12 Scores'!$C$5:$C$64=$M6)*('U11-U12 Scores'!$D$5:$D$64<>"")*('U11-U12 Scores'!$E$5:$E$64<>"")*('U11-U12 Scores'!$D$5:$D$64>'U11-U12 Scores'!$E$5:$E$64))+SUMPRODUCT(('U11-U12 Scores'!$F$5:$F$64=$M6)*('U11-U12 Scores'!$D$5:$D$64<>"")*('U11-U12 Scores'!$E$5:$E$64<>"")*('U11-U12 Scores'!$E$5:$E$64>'U11-U12 Scores'!$D$5:$D$64)) -> 0 | P6: =SUMPRODUCT((('U11-U12 Scores'!$C$5:$C$64=$M6)+('U11-U12 Scores'!$F$5:$F$64=$M6))*('U11-U12 Scores'!$D$5:$D$64<>"")*('U11-U12 Scores'!$E$5:$E$64<>"")*('U11-U12 Scores'!$D$5:$D$64='U11-U12 Scores'!$E$5:$E$64)) -> 0 | Q6: =$N6-$O6-$P6 -> 0 | R6: =SUMPRODUCT(('U11-U12 Scores'!$C$5:$C$64=$M6)*('U11-U12 Scores'!$D$5:$D$64<>"")*('U11-U12 Scores'!$E$5:$E$64<>"")*'U11-U12 Scores'!$D$5:$D$64)+SUMPRODUCT(('U11-U12 Scores'!$F$5:$F$64=$M6)*('U11-U12 Scores'!$D$5:$D$64<>"")*('U11-U12 Scores'!$E$5:$E$64<>"")*'U11-U12 Scores'!$E$5:$E$64) -> 0 | S6: =SUMPRODUCT(('U11-U12 Scores'!$C$5:$C$64=$M6)*('U11-U12 Scores'!$D$5:$D$64<>"")*('U11-U12 Scores'!$E$5:$E$64<>"")*'U11-U12 Scores'!$E$5:$E$64)+SUMPRODUCT(('U11-U12 Scores'!$F$5:$F$64=$M6)*('U11-U12 Scores'!$D$5:$D$64<>"")*('U11-U12 Scores'!$E$5:$E$64<>"")*'U11-U12 Scores'!$D$5:$D$64) -> 0 | T6: =$R6-$S6 -> 0 | U6: =3*$O6+$P6 -> 0 | V6: =$U6*1000000+($T6+500)*1000+$R6+(12-ROW())*0.01 -> 500000.06
A7: 2 | B7: =INDEX($M$6:$M$11,$L7) -> Germany | C7: =INDEX($N$6:$N$11,$L7) -> 0 | D7: =INDEX($O$6:$O$11,$L7) -> 0 | E7: =INDEX($P$6:$P$11,$L7) -> 0 | F7: =INDEX($Q$6:$Q$11,$L7) -> 0 | G7: =INDEX($R$6:$R$11,$L7) -> 0 | H7: =INDEX($S$6:$S$11,$L7) -> 0 | I7: =INDEX($T$6:$T$11,$L7) -> 0 | J7: =INDEX($U$6:$U$11,$L7) -> 0 | L7: =MATCH(LARGE($V$6:$V$11,ROW()-5),$V$6:$V$11,0) -> 2 | M7: Germany | N7: =SUMPRODUCT(('U11-U12 Scores'!$C$5:$C$64=$M7)*('U11-U12 Scores'!$D$5:$D$64<>"")*('U11-U12 Scores'!$E$5:$E$64<>""))+SUMPRODUCT(('U11-U12 Scores'!$F$5:$F$64=$M7)*('U11-U12 Scores'!$D$5:$D$64<>"")*('U11-U12 Scores'!$E$5:$E$64<>"")) -> 0 | O7: =SUMPRODUCT(('U11-U12 Scores'!$C$5:$C$64=$M7)*('U11-U12 Scores'!$D$5:$D$64<>"")*('U11-U12 Scores'!$E$5:$E$64<>"")*('U11-U12 Scores'!$D$5:$D$64>'U11-U12 Scores'!$E$5:$E$64))+SUMPRODUCT(('U11-U12 Scores'!$F$5:$F$64=$M7)*('U11-U12 Scores'!$D$5:$D$64<>"")*('U11-U12 Scores'!$E$5:$E$64<>"")*('U11-U12 Scores'!$E$5:$E$64>'U11-U12 Scores'!$D$5:$D$64)) -> 0 | P7: =SUMPRODUCT((('U11-U12 Scores'!$C$5:$C$64=$M7)+('U11-U12 Scores'!$F$5:$F$64=$M7))*('U11-U12 Scores'!$D$5:$D$64<>"")*('U11-U12 Scores'!$E$5:$E$64<>"")*('U11-U12 Scores'!$D$5:$D$64='U11-U12 Scores'!$E$5:$E$64)) -> 0 | Q7: =$N7-$O7-$P7 -> 0 | R7: =SUMPRODUCT(('U11-U12 Scores'!$C$5:$C$64=$M7)*('U11-U12 Scores'!$D$5:$D$64<>"")*('U11-U12 Scores'!$E$5:$E$64<>"")*'U11-U12 Scores'!$D$5:$D$64)+SUMPRODUCT(('U11-U12 Scores'!$F$5:$F$64=$M7)*('U11-U12 Scores'!$D$5:$D$64<>"")*('U11-U12 Scores'!$E$5:$E$64<>"")*'U11-U12 Scores'!$E$5:$E$64) -> 0 | S7: =SUMPRODUCT(('U11-U12 Scores'!$C$5:$C$64=$M7)*('U11-U12 Scores'!$D$5:$D$64<>"")*('U11-U12 Scores'!$E$5:$E$64<>"")*'U11-U12 Scores'!$E$5:$E$64)+SUMPRODUCT(('U11-U12 Scores'!$F$5:$F$64=$M7)*('U11-U12 Scores'!$D$5:$D$64<>"")*('U11-U12 Scores'!$E$5:$E$64<>"")*'U11-U12 Scores'!$D$5:$D$64) -> 0 | T7: =$R7-$S7 -> 0 | U7: =3*$O7+$P7 -> 0 | V7: =$U7*1000000+($T7+500)*1000+$R7+(12-ROW())*0.01 -> 500000.05
A8: 3 | B8: =INDEX($M$6:$M$11,$L8) -> Spain | C8: =INDEX($N$6:$N$11,$L8) -> 0 | D8: =INDEX($O$6:$O$11,$L8) -> 0 | E8: =INDEX($P$6:$P$11,$L8) -> 0 | F8: =INDEX($Q$6:$Q$11,$L8) -> 0 | G8: =INDEX($R$6:$R$11,$L8) -> 0 | H8: =INDEX($S$6:$S$11,$L8) -> 0 | I8: =INDEX($T$6:$T$11,$L8) -> 0 | J8: =INDEX($U$6:$U$11,$L8) -> 0 | L8: =MATCH(LARGE($V$6:$V$11,ROW()-5),$V$6:$V$11,0) -> 3 | M8: Spain | N8: =SUMPRODUCT(('U11-U12 Scores'!$C$5:$C$64=$M8)*('U11-U12 Scores'!$D$5:$D$64<>"")*('U11-U12 Scores'!$E$5:$E$64<>""))+SUMPRODUCT(('U11-U12 Scores'!$F$5:$F$64=$M8)*('U11-U12 Scores'!$D$5:$D$64<>"")*('U11-U12 Scores'!$E$5:$E$64<>"")) -> 0 | O8: =SUMPRODUCT(('U11-U12 Scores'!$C$5:$C$64=$M8)*('U11-U12 Scores'!$D$5:$D$64<>"")*('U11-U12 Scores'!$E$5:$E$64<>"")*('U11-U12 Scores'!$D$5:$D$64>'U11-U12 Scores'!$E$5:$E$64))+SUMPRODUCT(('U11-U12 Scores'!$F$5:$F$64=$M8)*('U11-U12 Scores'!$D$5:$D$64<>"")*('U11-U12 Scores'!$E$5:$E$64<>"")*('U11-U12 Scores'!$E$5:$E$64>'U11-U12 Scores'!$D$5:$D$64)) -> 0 | P8: =SUMPRODUCT((('U11-U12 Scores'!$C$5:$C$64=$M8)+('U11-U12 Scores'!$F$5:$F$64=$M8))*('U11-U12 Scores'!$D$5:$D$64<>"")*('U11-U12 Scores'!$E$5:$E$64<>"")*('U11-U12 Scores'!$D$5:$D$64='U11-U12 Scores'!$E$5:$E$64)) -> 0 | Q8: =$N8-$O8-$P8 -> 0 | R8: =SUMPRODUCT(('U11-U12 Scores'!$C$5:$C$64=$M8)*('U11-U12 Scores'!$D$5:$D$64<>"")*('U11-U12 Scores'!$E$5:$E$64<>"")*'U11-U12 Scores'!$D$5:$D$64)+SUMPRODUCT(('U11-U12 Scores'!$F$5:$F$64=$M8)*('U11-U12 Scores'!$D$5:$D$64<>"")*('U11-U12 Scores'!$E$5:$E$64<>"")*'U11-U12 Scores'!$E$5:$E$64) -> 0 | S8: =SUMPRODUCT(('U11-U12 Scores'!$C$5:$C$64=$M8)*('U11-U12 Scores'!$D$5:$D$64<>"")*('U11-U12 Scores'!$E$5:$E$64<>"")*'U11-U12 Scores'!$E$5:$E$64)+SUMPRODUCT(('U11-U12 Scores'!$F$5:$F$64=$M8)*('U11-U12 Scores'!$D$5:$D$64<>"")*('U11-U12 Scores'!$E$5:$E$64<>"")*'U11-U12 Scores'!$D$5:$D$64) -> 0 | T8: =$R8-$S8 -> 0 | U8: =3*$O8+$P8 -> 0 | V8: =$U8*1000000+($T8+500)*1000+$R8+(12-ROW())*0.01 -> 500000.04
A9: 4 | B9: =INDEX($M$6:$M$11,$L9) -> Netherlands | C9: =INDEX($N$6:$N$11,$L9) -> 0 | D9: =INDEX($O$6:$O$11,$L9) -> 0 | E9: =INDEX($P$6:$P$11,$L9) -> 0 | F9: =INDEX($Q$6:$Q$11,$L9) -> 0 | G9: =INDEX($R$6:$R$11,$L9) -> 0 | H9: =INDEX($S$6:$S$11,$L9) -> 0 | I9: =INDEX($T$6:$T$11,$L9) -> 0 | J9: =INDEX($U$6:$U$11,$L9) -> 0 | L9: =MATCH(LARGE($V$6:$V$11,ROW()-5),$V$6:$V$11,0) -> 4 | M9: Netherlands | N9: =SUMPRODUCT(('U11-U12 Scores'!$C$5:$C$64=$M9)*('U11-U12 Scores'!$D$5:$D$64<>"")*('U11-U12 Scores'!$E$5:$E$64<>""))+SUMPRODUCT(('U11-U12 Scores'!$F$5:$F$64=$M9)*('U11-U12 Scores'!$D$5:$D$64<>"")*('U11-U12 Scores'!$E$5:$E$64<>"")) -> 0 | O9: =SUMPRODUCT(('U11-U12 Scores'!$C$5:$C$64=$M9)*('U11-U12 Scores'!$D$5:$D$64<>"")*('U11-U12 Scores'!$E$5:$E$64<>"")*('U11-U12 Scores'!$D$5:$D$64>'U11-U12 Scores'!$E$5:$E$64))+SUMPRODUCT(('U11-U12 Scores'!$F$5:$F$64=$M9)*('U11-U12 Scores'!$D$5:$D$64<>"")*('U11-U12 Scores'!$E$5:$E$64<>"")*('U11-U12 Scores'!$E$5:$E$64>'U11-U12 Scores'!$D$5:$D$64)) -> 0 | P9: =SUMPRODUCT((('U11-U12 Scores'!$C$5:$C$64=$M9)+('U11-U12 Scores'!$F$5:$F$64=$M9))*('U11-U12 Scores'!$D$5:$D$64<>"")*('U11-U12 Scores'!$E$5:$E$64<>"")*('U11-U12 Scores'!$D$5:$D$64='U11-U12 Scores'!$E$5:$E$64)) -> 0 | Q9: =$N9-$O9-$P9 -> 0 | R9: =SUMPRODUCT(('U11-U12 Scores'!$C$5:$C$64=$M9)*('U11-U12 Scores'!$D$5:$D$64<>"")*('U11-U12 Scores'!$E$5:$E$64<>"")*'U11-U12 Scores'!$D$5:$D$64)+SUMPRODUCT(('U11-U12 Scores'!$F$5:$F$64=$M9)*('U11-U12 Scores'!$D$5:$D$64<>"")*('U11-U12 Scores'!$E$5:$E$64<>"")*'U11-U12 Scores'!$E$5:$E$64) -> 0 | S9: =SUMPRODUCT(('U11-U12 Scores'!$C$5:$C$64=$M9)*('U11-U12 Scores'!$D$5:$D$64<>"")*('U11-U12 Scores'!$E$5:$E$64<>"")*'U11-U12 Scores'!$E$5:$E$64)+SUMPRODUCT(('U11-U12 Scores'!$F$5:$F$64=$M9)*('U11-U12 Scores'!$D$5:$D$64<>"")*('U11-U12 Scores'!$E$5:$E$64<>"")*'U11-U12 Scores'!$D$5:$D$64) -> 0 | T9: =$R9-$S9 -> 0 | U9: =3*$O9+$P9 -> 0 | V9: =$U9*1000000+($T9+500)*1000+$R9+(12-ROW())*0.01 -> 500000.03
A10: 5 | B10: =INDEX($M$6:$M$11,$L10) -> Portugal | C10: =INDEX($N$6:$N$11,$L10) -> 0 | D10: =INDEX($O$6:$O$11,$L10) -> 0 | E10: =INDEX($P$6:$P$11,$L10) -> 0 | F10: =INDEX($Q$6:$Q$11,$L10) -> 0 | G10: =INDEX($R$6:$R$11,$L10) -> 0 | H10: =INDEX($S$6:$S$11,$L10) -> 0 | I10: =INDEX($T$6:$T$11,$L10) -> 0 | J10: =INDEX($U$6:$U$11,$L10) -> 0 | L10: =MATCH(LARGE($V$6:$V$11,ROW()-5),$V$6:$V$11,0) -> 5 | M10: Portugal | N10: =SUMPRODUCT(('U11-U12 Scores'!$C$5:$C$64=$M10)*('U11-U12 Scores'!$D$5:$D$64<>"")*('U11-U12 Scores'!$E$5:$E$64<>""))+SUMPRODUCT(('U11-U12 Scores'!$F$5:$F$64=$M10)*('U11-U12 Scores'!$D$5:$D$64<>"")*('U11-U12 Scores'!$E$5:$E$64<>"")) -> 0 | O10: =SUMPRODUCT(('U11-U12 Scores'!$C$5:$C$64=$M10)*('U11-U12 Scores'!$D$5:$D$64<>"")*('U11-U12 Scores'!$E$5:$E$64<>"")*('U11-U12 Scores'!$D$5:$D$64>'U11-U12 Scores'!$E$5:$E$64))+SUMPRODUCT(('U11-U12 Scores'!$F$5:$F$64=$M10)*('U11-U12 Scores'!$D$5:$D$64<>"")*('U11-U12 Scores'!$E$5:$E$64<>"")*('U11-U12 Scores'!$E$5:$E$64>'U11-U12 Scores'!$D$5:$D$64)) -> 0 | P10: =SUMPRODUCT((('U11-U12 Scores'!$C$5:$C$64=$M10)+('U11-U12 Scores'!$F$5:$F$64=$M10))*('U11-U12 Scores'!$D$5:$D$64<>"")*('U11-U12 Scores'!$E$5:$E$64<>"")*('U11-U12 Scores'!$D$5:$D$64='U11-U12 Scores'!$E$5:$E$64)) -> 0 | Q10: =$N10-$O10-$P10 -> 0 | R10: =SUMPRODUCT(('U11-U12 Scores'!$C$5:$C$64=$M10)*('U11-U12 Scores'!$D$5:$D$64<>"")*('U11-U12 Scores'!$E$5:$E$64<>"")*'U11-U12 Scores'!$D$5:$D$64)+SUMPRODUCT(('U11-U12 Scores'!$F$5:$F$64=$M10)*('U11-U12 Scores'!$D$5:$D$64<>"")*('U11-U12 Scores'!$E$5:$E$64<>"")*'U11-U12 Scores'!$E$5:$E$64) -> 0 | S10: =SUMPRODUCT(('U11-U12 Scores'!$C$5:$C$64=$M10)*('U11-U12 Scores'!$D$5:$D$64<>"")*('U11-U12 Scores'!$E$5:$E$64<>"")*'U11-U12 Scores'!$E$5:$E$64)+SUMPRODUCT(('U11-U12 Scores'!$F$5:$F$64=$M10)*('U11-U12 Scores'!$D$5:$D$64<>"")*('U11-U12 Scores'!$E$5:$E$64<>"")*'U11-U12 Scores'!$D$5:$D$64) -> 0 | T10: =$R10-$S10 -> 0 | U10: =3*$O10+$P10 -> 0 | V10: =$U10*1000000+($T10+500)*1000+$R10+(12-ROW())*0.01 -> 500000.02
A11: 6 | B11: =INDEX($M$6:$M$11,$L11) -> Scotland | C11: =INDEX($N$6:$N$11,$L11) -> 0 | D11: =INDEX($O$6:$O$11,$L11) -> 0 | E11: =INDEX($P$6:$P$11,$L11) -> 0 | F11: =INDEX($Q$6:$Q$11,$L11) -> 0 | G11: =INDEX($R$6:$R$11,$L11) -> 0 | H11: =INDEX($S$6:$S$11,$L11) -> 0 | I11: =INDEX($T$6:$T$11,$L11) -> 0 | J11: =INDEX($U$6:$U$11,$L11) -> 0 | L11: =MATCH(LARGE($V$6:$V$11,ROW()-5),$V$6:$V$11,0) -> 6 | M11: Scotland | N11: =SUMPRODUCT(('U11-U12 Scores'!$C$5:$C$64=$M11)*('U11-U12 Scores'!$D$5:$D$64<>"")*('U11-U12 Scores'!$E$5:$E$64<>""))+SUMPRODUCT(('U11-U12 Scores'!$F$5:$F$64=$M11)*('U11-U12 Scores'!$D$5:$D$64<>"")*('U11-U12 Scores'!$E$5:$E$64<>"")) -> 0 | O11: =SUMPRODUCT(('U11-U12 Scores'!$C$5:$C$64=$M11)*('U11-U12 Scores'!$D$5:$D$64<>"")*('U11-U12 Scores'!$E$5:$E$64<>"")*('U11-U12 Scores'!$D$5:$D$64>'U11-U12 Scores'!$E$5:$E$64))+SUMPRODUCT(('U11-U12 Scores'!$F$5:$F$64=$M11)*('U11-U12 Scores'!$D$5:$D$64<>"")*('U11-U12 Scores'!$E$5:$E$64<>"")*('U11-U12 Scores'!$E$5:$E$64>'U11-U12 Scores'!$D$5:$D$64)) -> 0 | P11: =SUMPRODUCT((('U11-U12 Scores'!$C$5:$C$64=$M11)+('U11-U12 Scores'!$F$5:$F$64=$M11))*('U11-U12 Scores'!$D$5:$D$64<>"")*('U11-U12 Scores'!$E$5:$E$64<>"")*('U11-U12 Scores'!$D$5:$D$64='U11-U12 Scores'!$E$5:$E$64)) -> 0 | Q11: =$N11-$O11-$P11 -> 0 | R11: =SUMPRODUCT(('U11-U12 Scores'!$C$5:$C$64=$M11)*('U11-U12 Scores'!$D$5:$D$64<>"")*('U11-U12 Scores'!$E$5:$E$64<>"")*'U11-U12 Scores'!$D$5:$D$64)+SUMPRODUCT(('U11-U12 Scores'!$F$5:$F$64=$M11)*('U11-U12 Scores'!$D$5:$D$64<>"")*('U11-U12 Scores'!$E$5:$E$64<>"")*'U11-U12 Scores'!$E$5:$E$64) -> 0 | S11: =SUMPRODUCT(('U11-U12 Scores'!$C$5:$C$64=$M11)*('U11-U12 Scores'!$D$5:$D$64<>"")*('U11-U12 Scores'!$E$5:$E$64<>"")*'U11-U12 Scores'!$E$5:$E$64)+SUMPRODUCT(('U11-U12 Scores'!$F$5:$F$64=$M11)*('U11-U12 Scores'!$D$5:$D$64<>"")*('U11-U12 Scores'!$E$5:$E$64<>"")*'U11-U12 Scores'!$D$5:$D$64) -> 0 | T11: =$R11-$S11 -> 0 | U11: =3*$O11+$P11 -> 0 | V11: =$U11*1000000+($T11+500)*1000+$R11+(12-ROW())*0.01 -> 500000.01
A14: Group 2
A15: Pos | B15: Team | C15: P | D15: W | E15: D | F15: L | G15: GF | H15: GA | I15: GD | J15: Pts
A16: 1 | B16: =INDEX($M$16:$M$21,$L16) -> France | C16: =INDEX($N$16:$N$21,$L16) -> 0 | D16: =INDEX($O$16:$O$21,$L16) -> 0 | E16: =INDEX($P$16:$P$21,$L16) -> 0 | F16: =INDEX($Q$16:$Q$21,$L16) -> 0 | G16: =INDEX($R$16:$R$21,$L16) -> 0 | H16: =INDEX($S$16:$S$21,$L16) -> 0 | I16: =INDEX($T$16:$T$21,$L16) -> 0 | J16: =INDEX($U$16:$U$21,$L16) -> 0 | L16: =MATCH(LARGE($V$16:$V$21,ROW()-15),$V$16:$V$21,0) -> 1 | M16: France | N16: =SUMPRODUCT(('U11-U12 Scores'!$C$5:$C$64=$M16)*('U11-U12 Scores'!$D$5:$D$64<>"")*('U11-U12 Scores'!$E$5:$E$64<>""))+SUMPRODUCT(('U11-U12 Scores'!$F$5:$F$64=$M16)*('U11-U12 Scores'!$D$5:$D$64<>"")*('U11-U12 Scores'!$E$5:$E$64<>"")) -> 0 | O16: =SUMPRODUCT(('U11-U12 Scores'!$C$5:$C$64=$M16)*('U11-U12 Scores'!$D$5:$D$64<>"")*('U11-U12 Scores'!$E$5:$E$64<>"")*('U11-U12 Scores'!$D$5:$D$64>'U11-U12 Scores'!$E$5:$E$64))+SUMPRODUCT(('U11-U12 Scores'!$F$5:$F$64=$M16)*('U11-U12 Scores'!$D$5:$D$64<>"")*('U11-U12 Scores'!$E$5:$E$64<>"")*('U11-U12 Scores'!$E$5:$E$64>'U11-U12 Scores'!$D$5:$D$64)) -> 0 | P16: =SUMPRODUCT((('U11-U12 Scores'!$C$5:$C$64=$M16)+('U11-U12 Scores'!$F$5:$F$64=$M16))*('U11-U12 Scores'!$D$5:$D$64<>"")*('U11-U12 Scores'!$E$5:$E$64<>"")*('U11-U12 Scores'!$D$5:$D$64='U11-U12 Scores'!$E$5:$E$64)) -> 0 | Q16: =$N16-$O16-$P16 -> 0 | R16: =SUMPRODUCT(('U11-U12 Scores'!$C$5:$C$64=$M16)*('U11-U12 Scores'!$D$5:$D$64<>"")*('U11-U12 Scores'!$E$5:$E$64<>"")*'U11-U12 Scores'!$D$5:$D$64)+SUMPRODUCT(('U11-U12 Scores'!$F$5:$F$64=$M16)*('U11-U12 Scores'!$D$5:$D$64<>"")*('U11-U12 Scores'!$E$5:$E$64<>"")*'U11-U12 Scores'!$E$5:$E$64) -> 0 | S16: =SUMPRODUCT(('U11-U12 Scores'!$C$5:$C$64=$M16)*('U11-U12 Scores'!$D$5:$D$64<>"")*('U11-U12 Scores'!$E$5:$E$64<>"")*'U11-U12 Scores'!$E$5:$E$64)+SUMPRODUCT(('U11-U12 Scores'!$F$5:$F$64=$M16)*('U11-U12 Scores'!$D$5:$D$64<>"")*('U11-U12 Scores'!$E$5:$E$64<>"")*'U11-U12 Scores'!$D$5:$D$64) -> 0 | T16: =$R16-$S16 -> 0 | U16: =3*$O16+$P16 -> 0 | V16: =$U16*1000000+($T16+500)*1000+$R16+(22-ROW())*0.01 -> 500000.06
A17: 2 | B17: =INDEX($M$16:$M$21,$L17) -> England | C17: =INDEX($N$16:$N$21,$L17) -> 0 | D17: =INDEX($O$16:$O$21,$L17) -> 0 | E17: =INDEX($P$16:$P$21,$L17) -> 0 | F17: =INDEX($Q$16:$Q$21,$L17) -> 0 | G17: =INDEX($R$16:$R$21,$L17) -> 0 | H17: =INDEX($S$16:$S$21,$L17) -> 0 | I17: =INDEX($T$16:$T$21,$L17) -> 0 | J17: =INDEX($U$16:$U$21,$L17) -> 0 | L17: =MATCH(LARGE($V$16:$V$21,ROW()-15),$V$16:$V$21,0) -> 2 | M17: England | N17: =SUMPRODUCT(('U11-U12 Scores'!$C$5:$C$64=$M17)*('U11-U12 Scores'!$D$5:$D$64<>"")*('U11-U12 Scores'!$E$5:$E$64<>""))+SUMPRODUCT(('U11-U12 Scores'!$F$5:$F$64=$M17)*('U11-U12 Scores'!$D$5:$D$64<>"")*('U11-U12 Scores'!$E$5:$E$64<>"")) -> 0 | O17: =SUMPRODUCT(('U11-U12 Scores'!$C$5:$C$64=$M17)*('U11-U12 Scores'!$D$5:$D$64<>"")*('U11-U12 Scores'!$E$5:$E$64<>"")*('U11-U12 Scores'!$D$5:$D$64>'U11-U12 Scores'!$E$5:$E$64))+SUMPRODUCT(('U11-U12 Scores'!$F$5:$F$64=$M17)*('U11-U12 Scores'!$D$5:$D$64<>"")*('U11-U12 Scores'!$E$5:$E$64<>"")*('U11-U12 Scores'!$E$5:$E$64>'U11-U12 Scores'!$D$5:$D$64)) -> 0 | P17: =SUMPRODUCT((('U11-U12 Scores'!$C$5:$C$64=$M17)+('U11-U12 Scores'!$F$5:$F$64=$M17))*('U11-U12 Scores'!$D$5:$D$64<>"")*('U11-U12 Scores'!$E$5:$E$64<>"")*('U11-U12 Scores'!$D$5:$D$64='U11-U12 Scores'!$E$5:$E$64)) -> 0 | Q17: =$N17-$O17-$P17 -> 0 | R17: =SUMPRODUCT(('U11-U12 Scores'!$C$5:$C$64=$M17)*('U11-U12 Scores'!$D$5:$D$64<>"")*('U11-U12 Scores'!$E$5:$E$64<>"")*'U11-U12 Scores'!$D$5:$D$64)+SUMPRODUCT(('U11-U12 Scores'!$F$5:$F$64=$M17)*('U11-U12 Scores'!$D$5:$D$64<>"")*('U11-U12 Scores'!$E$5:$E$64<>"")*'U11-U12 Scores'!$E$5:$E$64) -> 0 | S17: =SUMPRODUCT(('U11-U12 Scores'!$C$5:$C$64=$M17)*('U11-U12 Scores'!$D$5:$D$64<>"")*('U11-U12 Scores'!$E$5:$E$64<>"")*'U11-U12 Scores'!$E$5:$E$64)+SUMPRODUCT(('U11-U12 Scores'!$F$5:$F$64=$M17)*('U11-U12 Scores'!$D$5:$D$64<>"")*('U11-U12 Scores'!$E$5:$E$64<>"")*'U11-U12 Scores'!$D$5:$D$64) -> 0 | T17: =$R17-$S17 -> 0 | U17: =3*$O17+$P17 -> 0 | V17: =$U17*1000000+($T17+500)*1000+$R17+(22-ROW())*0.01 -> 500000.05
A18: 3 | B18: =INDEX($M$16:$M$21,$L18) -> Argentina | C18: =INDEX($N$16:$N$21,$L18) -> 0 | D18: =INDEX($O$16:$O$21,$L18) -> 0 | E18: =INDEX($P$16:$P$21,$L18) -> 0 | F18: =INDEX($Q$16:$Q$21,$L18) -> 0 | G18: =INDEX($R$16:$R$21,$L18) -> 0 | H18: =INDEX($S$16:$S$21,$L18) -> 0 | I18: =INDEX($T$16:$T$21,$L18) -> 0 | J18: =INDEX($U$16:$U$21,$L18) -> 0 | L18: =MATCH(LARGE($V$16:$V$21,ROW()-15),$V$16:$V$21,0) -> 3 | M18: Argentina | N18: =SUMPRODUCT(('U11-U12 Scores'!$C$5:$C$64=$M18)*('U11-U12 Scores'!$D$5:$D$64<>"")*('U11-U12 Scores'!$E$5:$E$64<>""))+SUMPRODUCT(('U11-U12 Scores'!$F$5:$F$64=$M18)*('U11-U12 Scores'!$D$5:$D$64<>"")*('U11-U12 Scores'!$E$5:$E$64<>"")) -> 0 | O18: =SUMPRODUCT(('U11-U12 Scores'!$C$5:$C$64=$M18)*('U11-U12 Scores'!$D$5:$D$64<>"")*('U11-U12 Scores'!$E$5:$E$64<>"")*('U11-U12 Scores'!$D$5:$D$64>'U11-U12 Scores'!$E$5:$E$64))+SUMPRODUCT(('U11-U12 Scores'!$F$5:$F$64=$M18)*('U11-U12 Scores'!$D$5:$D$64<>"")*('U11-U12 Scores'!$E$5:$E$64<>"")*('U11-U12 Scores'!$E$5:$E$64>'U11-U12 Scores'!$D$5:$D$64)) -> 0 | P18: =SUMPRODUCT((('U11-U12 Scores'!$C$5:$C$64=$M18)+('U11-U12 Scores'!$F$5:$F$64=$M18))*('U11-U12 Scores'!$D$5:$D$64<>"")*('U11-U12 Scores'!$E$5:$E$64<>"")*('U11-U12 Scores'!$D$5:$D$64='U11-U12 Scores'!$E$5:$E$64)) -> 0 | Q18: =$N18-$O18-$P18 -> 0 | R18: =SUMPRODUCT(('U11-U12 Scores'!$C$5:$C$64=$M18)*('U11-U12 Scores'!$D$5:$D$64<>"")*('U11-U12 Scores'!$E$5:$E$64<>"")*'U11-U12 Scores'!$D$5:$D$64)+SUMPRODUCT(('U11-U12 Scores'!$F$5:$F$64=$M18)*('U11-U12 Scores'!$D$5:$D$64<>"")*('U11-U12 Scores'!$E$5:$E$64<>"")*'U11-U12 Scores'!$E$5:$E$64) -> 0 | S18: =SUMPRODUCT(('U11-U12 Scores'!$C$5:$C$64=$M18)*('U11-U12 Scores'!$D$5:$D$64<>"")*('U11-U12 Scores'!$E$5:$E$64<>"")*'U11-U12 Scores'!$E$5:$E$64)+SUMPRODUCT(('U11-U12 Scores'!$F$5:$F$64=$M18)*('U11-U12 Scores'!$D$5:$D$64<>"")*('U11-U12 Scores'!$E$5:$E$64<>"")*'U11-U12 Scores'!$D$5:$D$64) -> 0 | T18: =$R18-$S18 -> 0 | U18: =3*$O18+$P18 -> 0 | V18: =$U18*1000000+($T18+500)*1000+$R18+(22-ROW())*0.01 -> 500000.04
A19: 4 | B19: =INDEX($M$16:$M$21,$L19) -> Mexico | C19: =INDEX($N$16:$N$21,$L19) -> 0 | D19: =INDEX($O$16:$O$21,$L19) -> 0 | E19: =INDEX($P$16:$P$21,$L19) -> 0 | F19: =INDEX($Q$16:$Q$21,$L19) -> 0 | G19: =INDEX($R$16:$R$21,$L19) -> 0 | H19: =INDEX($S$16:$S$21,$L19) -> 0 | I19: =INDEX($T$16:$T$21,$L19) -> 0 | J19: =INDEX($U$16:$U$21,$L19) -> 0 | L19: =MATCH(LARGE($V$16:$V$21,ROW()-15),$V$16:$V$21,0) -> 4 | M19: Mexico | N19: =SUMPRODUCT(('U11-U12 Scores'!$C$5:$C$64=$M19)*('U11-U12 Scores'!$D$5:$D$64<>"")*('U11-U12 Scores'!$E$5:$E$64<>""))+SUMPRODUCT(('U11-U12 Scores'!$F$5:$F$64=$M19)*('U11-U12 Scores'!$D$5:$D$64<>"")*('U11-U12 Scores'!$E$5:$E$64<>"")) -> 0 | O19: =SUMPRODUCT(('U11-U12 Scores'!$C$5:$C$64=$M19)*('U11-U12 Scores'!$D$5:$D$64<>"")*('U11-U12 Scores'!$E$5:$E$64<>"")*('U11-U12 Scores'!$D$5:$D$64>'U11-U12 Scores'!$E$5:$E$64))+SUMPRODUCT(('U11-U12 Scores'!$F$5:$F$64=$M19)*('U11-U12 Scores'!$D$5:$D$64<>"")*('U11-U12 Scores'!$E$5:$E$64<>"")*('U11-U12 Scores'!$E$5:$E$64>'U11-U12 Scores'!$D$5:$D$64)) -> 0 | P19: =SUMPRODUCT((('U11-U12 Scores'!$C$5:$C$64=$M19)+('U11-U12 Scores'!$F$5:$F$64=$M19))*('U11-U12 Scores'!$D$5:$D$64<>"")*('U11-U12 Scores'!$E$5:$E$64<>"")*('U11-U12 Scores'!$D$5:$D$64='U11-U12 Scores'!$E$5:$E$64)) -> 0 | Q19: =$N19-$O19-$P19 -> 0 | R19: =SUMPRODUCT(('U11-U12 Scores'!$C$5:$C$64=$M19)*('U11-U12 Scores'!$D$5:$D$64<>"")*('U11-U12 Scores'!$E$5:$E$64<>"")*'U11-U12 Scores'!$D$5:$D$64)+SUMPRODUCT(('U11-U12 Scores'!$F$5:$F$64=$M19)*('U11-U12 Scores'!$D$5:$D$64<>"")*('U11-U12 Scores'!$E$5:$E$64<>"")*'U11-U12 Scores'!$E$5:$E$64) -> 0 | S19: =SUMPRODUCT(('U11-U12 Scores'!$C$5:$C$64=$M19)*('U11-U12 Scores'!$D$5:$D$64<>"")*('U11-U12 Scores'!$E$5:$E$64<>"")*'U11-U12 Scores'!$E$5:$E$64)+SUMPRODUCT(('U11-U12 Scores'!$F$5:$F$64=$M19)*('U11-U12 Scores'!$D$5:$D$64<>"")*('U11-U12 Scores'!$E$5:$E$64<>"")*'U11-U12 Scores'!$D$5:$D$64) -> 0 | T19: =$R19-$S19 -> 0 | U19: =3*$O19+$P19 -> 0 | V19: =$U19*1000000+($T19+500)*1000+$R19+(22-ROW())*0.01 -> 500000.03
A20: 5 | B20: =INDEX($M$16:$M$21,$L20) -> Canada | C20: =INDEX($N$16:$N$21,$L20) -> 0 | D20: =INDEX($O$16:$O$21,$L20) -> 0 | E20: =INDEX($P$16:$P$21,$L20) -> 0 | F20: =INDEX($Q$16:$Q$21,$L20) -> 0 | G20: =INDEX($R$16:$R$21,$L20) -> 0 | H20: =INDEX($S$16:$S$21,$L20) -> 0 | I20: =INDEX($T$16:$T$21,$L20) -> 0 | J20: =INDEX($U$16:$U$21,$L20) -> 0 | L20: =MATCH(LARGE($V$16:$V$21,ROW()-15),$V$16:$V$21,0) -> 5 | M20: Canada | N20: =SUMPRODUCT(('U11-U12 Scores'!$C$5:$C$64=$M20)*('U11-U12 Scores'!$D$5:$D$64<>"")*('U11-U12 Scores'!$E$5:$E$64<>""))+SUMPRODUCT(('U11-U12 Scores'!$F$5:$F$64=$M20)*('U11-U12 Scores'!$D$5:$D$64<>"")*('U11-U12 Scores'!$E$5:$E$64<>"")) -> 0 | O20: =SUMPRODUCT(('U11-U12 Scores'!$C$5:$C$64=$M20)*('U11-U12 Scores'!$D$5:$D$64<>"")*('U11-U12 Scores'!$E$5:$E$64<>"")*('U11-U12 Scores'!$D$5:$D$64>'U11-U12 Scores'!$E$5:$E$64))+SUMPRODUCT(('U11-U12 Scores'!$F$5:$F$64=$M20)*('U11-U12 Scores'!$D$5:$D$64<>"")*('U11-U12 Scores'!$E$5:$E$64<>"")*('U11-U12 Scores'!$E$5:$E$64>'U11-U12 Scores'!$D$5:$D$64)) -> 0 | P20: =SUMPRODUCT((('U11-U12 Scores'!$C$5:$C$64=$M20)+('U11-U12 Scores'!$F$5:$F$64=$M20))*('U11-U12 Scores'!$D$5:$D$64<>"")*('U11-U12 Scores'!$E$5:$E$64<>"")*('U11-U12 Scores'!$D$5:$D$64='U11-U12 Scores'!$E$5:$E$64)) -> 0 | Q20: =$N20-$O20-$P20 -> 0 | R20: =SUMPRODUCT(('U11-U12 Scores'!$C$5:$C$64=$M20)*('U11-U12 Scores'!$D$5:$D$64<>"")*('U11-U12 Scores'!$E$5:$E$64<>"")*'U11-U12 Scores'!$D$5:$D$64)+SUMPRODUCT(('U11-U12 Scores'!$F$5:$F$64=$M20)*('U11-U12 Scores'!$D$5:$D$64<>"")*('U11-U12 Scores'!$E$5:$E$64<>"")*'U11-U12 Scores'!$E$5:$E$64) -> 0 | S20: =SUMPRODUCT(('U11-U12 Scores'!$C$5:$C$64=$M20)*('U11-U12 Scores'!$D$5:$D$64<>"")*('U11-U12 Scores'!$E$5:$E$64<>"")*'U11-U12 Scores'!$E$5:$E$64)+SUMPRODUCT(('U11-U12 Scores'!$F$5:$F$64=$M20)*('U11-U12 Scores'!$D$5:$D$64<>"")*('U11-U12 Scores'!$E$5:$E$64<>"")*'U11-U12 Scores'!$D$5:$D$64) -> 0 | T20: =$R20-$S20 -> 0 | U20: =3*$O20+$P20 -> 0 | V20: =$U20*1000000+($T20+500)*1000+$R20+(22-ROW())*0.01 -> 500000.02
